Workbook
Name ARTICLE: _xlfn.ANCHORARRAY(ARTICLE!$A$2)
Name COMPO: 'MATRICE COMPO'!$A$2:$A$199
Name COMPOSITION: _xlfn.ANCHORARRAY(COMPOSITION!$A$2)
Name COMPOSITIONS: COMPOSITION!$B$1:$I$91
Name ETAPE: _xlfn.ANCHORARRAY('MAIN D OEUVRE'!$G$4)
Name MATERIAUX: _xlfn.ANCHORARRAY(MATERIAUX!$A$3)
Name MATRICE_ARTICLE: ARTICLE!$B:$O
Name MATRICE_COMPOSITION: COMPOSITION!$B:$N
Name MATRICE_MATERIAUX: MATERIAUX!$C:$AM
Name MATRICE_SERVICE: SERVICE!$B:$N
Name PAVAWALL_40_mm___OSB_8___STRUCT_150_mm___IZOLATIE_LEMN_150_mm___FOLIE___OSB_15: 'MATRICE COMPO'!$A$3:$A$199
Name PRESTATION: GESTION!$E$2:$E$9
Name SERVICE: _xlfn.ANCHORARRAY(SERVICE!$A$2)

Sheet GESTION
A1: PARAMETRE DE CHIFFRAGE | B1: VALEUR | C1: Unité | E1: PRESTATION | F1: MATRICE
A2: Déboursé horaire | B2: 22 | C2: €/hr | E2: SERVICE | F2: MATRICE_SERVICE
A3: Frais généraux | B3: 0.1 | C3: pourcent | E3: COMPOSITION | F3: MATRICE_COMPOSITION
A4: Bénéfice Article/compo | B4: 0.3 | C4: pourcent | E4: ARTICLE | F4: MATRICE_ARTICLE
A5: Bénéfice vente matériaux | B5: 0.2 | C5: pourcent | E5: MATERIAUX | F5: MATRICE_MATERIAUX
A6: Bénéfice Service | B6: 0 | C6: pourcent
A7: Conversion Lei --> Euro | B7: 4.85 | C7: Lei/€
A8: Conversion Euro --> Lei | B8: =1/B7 -> 0.20618557 | C8: €/Lei
A9: Quincaillerie | B9: 0.07 | C9: % de CA €

Sheet SERVICE
A1: Liste déroulante: | B1: COMPOSITION | C1: ID | D1: Unité | E1: Prix net | F1: Prix brut | G1: =GESTION!B6 -> 0 | H1: =GESTION!B3 -> 0.1
A2: {=_xlfn.UNIQUE(_xlfn._xlws.FILTER(B2:B1000,NOT(ISBLANK(B2:B1000))))} -> Etude Loftwood Construction | B2: Etude Loftwood Construction | D2: ens | E2: =IFERROR(F2+G2+H2,"") -> 660 | F2: 600 | G2: =IF(B2="","",F2*$G$1) -> 0 | H2: =IFERROR((F2+G2)*$H$1,"") -> 60
A3: Transport Camion standard | B3: Transport Camion standard | D3: ft | E3: =IFERROR(F3+G3+H3,"") -> 3850 | F3: 3500 | G3: =IF(B3="","",F3*$G$1) -> 0 | H3: =IFERROR((F3+G3)*$H$1,"") -> 350
A4: Transport Camion Mega | B4: Transport Camion Mega | D4: ft | E4: =IFERROR(F4+G4+H4,"") -> 4235 | F4: =F3*1.1 -> 3850 | G4: =IF(B4="","",F4*$G$1) -> 0 | H4: =IFERROR((F4+G4)*$H$1,"") -> 385
A5: Charpente industrielle | B5: Charpente industrielle | D5: m2 | E5: =IFERROR(F5+G5+H5,"") -> 38.5 | F5: 35 | G5: =IF(B5="","",F5*$G$1) -> 0 | H5: =IFERROR((F5+G5)*$H$1,"") -> 3.5
A6: Forfait quincaillerie | B6: Forfait quincaillerie | D6: ft | E6: =IFERROR(F6+G6+H6,"") -> 1100 | F6: 1000 | G6: =IF(B6="","",F6*$G$1) -> 0 | H6: =IFERROR((F6+G6)*$H$1,"") -> 100
A7: PSE CHANTIER | B7: PSE CHANTIER | D7: m2 | E7: =IFERROR(F7+G7+H7,"") -> 27.753 | F7: 25.23 | G7: =IF(B7="","",F7*$G$1) -> 0 | H7: =IFERROR((F7+G7)*$H$1,"") -> 2.523
A8: Transport camion tandem VAR (83) | B8: Transport camion tandem VAR (83) | D8: ft | E8: =IFERROR(F8+G8+H8,"") -> 2530 | F8: 2300 | G8: =IF(B8="","",F8*$G$1) -> 0 | H8: =IFERROR((F8+G8)*$H$1,"") -> 230 | I8: Reste a etre validee a la demande, en principe est 1,3 Euro / Km
A9: Transport camion standard BOUCHE-DU-RHONE (13) | B9: Transport camion standard BOUCHE-DU-RHONE (13) | D9: ft | E9: =IFERROR(F9+G9+H9,"") -> 2200 | F9: 2000 | G9: =IF(B9="","",F9*$G$1) -> 0 | H9: =IFERROR((F9+G9)*$H$1,"") -> 200
A10: Transport camion standard ISERE (38) | B10: Transport camion standard ISERE (38) | D10: ft | E10: =IFERROR(F10+G10+H10,"") -> 2530 | F10: 2300 | G10: =IF(B10="","",F10*$G$1) -> 0 | H10: =IFERROR((F10+G10)*$H$1,"") -> 230
A11: Déplacement | B11: Déplacement | D11: ft | E11: =IFERROR(F11+G11+H11,"") -> 1430 | F11: 1300 | G11: =IF(B11="","",F11*$G$1) -> 0 | H11: =IFERROR((F11+G11)*$H$1,"") -> 130
A12: Logement | B12: Logement | D12: j | E12: =IFERROR(F12+G12+H12,"") -> 165 | F12: =50*3 -> 150 | G12: =IF(B12="","",F12*$G$1) -> 0 | H12: =IFERROR((F12+G12)*$H$1,"") -> 15
A13: Montage chantier | B13: Montage chantier | D13: j | E13: =IFERROR(F13+G13+H13,"") -> 997.92 | F13: =37.8*3*8 -> 907.2 | G13: =IF(B13="","",F13*$G$1) -> 0 | H13: =IFERROR((F13+G13)*$H$1,"") -> 90.72
A14: Engin de levage | B14: Engin de levage | D14: ens | E14: =IFERROR(F14+G14+H14,"") -> 5720 | F14: =130*8*5 -> 5200 | G14: =IF(B14="","",F14*$G$1) -> 0 | H14: =IFERROR((F14+G14)*$H$1,"") -> 520
A15: Transport standard (75) | B15: Transport standard (75) | D15: ft | E15: =IFERROR(F15+G15+H15,"") -> 3146 | F15: =1.3*2200 -> 2860 | G15: =IF(B15="","",F15*$G$1) -> 0 | H15: =IFERROR((F15+G15)*$H$1,"") -> 286
A16: Déplacement (75) | B16: Déplacement (75) | D16: ft | E16: =IFERROR(F16+G16+H16,"") -> 2347.84 | F16: =2*(160+37.8*3*8) -> 2134.4 | G16: =IF(B16="","",F16*$G$1) -> 0 | H16: =IFERROR((F16+G16)*$H$1,"") -> 213.44
D17: =IFERROR(VLOOKUP(A17,'MATRICE COMPO'!$A:$H,3,FALSE),"") | E17: =IFERROR(F17+G17+H17,"") | G17: =IF(B17="","",F17*$G$1) | H17: =IFERROR((F17+G17)*$H$1,"")
D18: =IFERROR(VLOOKUP(A18,'MATRICE COMPO'!$A:$H,3,FALSE),"") | E18: =IFERROR(F18+G18+H18,"") | G18: =IF(B18="","",F18*$G$1) | H18: =IFERROR((F18+G18)*$H$1,"")
D19: =IFERROR(VLOOKUP(A19,'MATRICE COMPO'!$A:$H,3,FALSE),"") | E19: =IFERROR(F19+G19+H19,"") | G19: =IF(B19="","",F19*$G$1) | H19: =IFERROR((F19+G19)*$H$1,"")
D20: =IFERROR(VLOOKUP(A20,'MATRICE COMPO'!$A:$H,3,FALSE),"") | E20: =IFERROR(F20+G20+H20,"") | G20: =IF(B20="","",F20*$G$1) | H20: =IFERROR((F20+G20)*$H$1,"")
D21: =IFERROR(VLOOKUP(A21,'MATRICE COMPO'!$A:$H,3,FALSE),"") | E21: =IFERROR(F21+G21+H21,"") | G21: =IF(B21="","",F21*$G$1) | H21: =IFERROR((F21+G21)*$H$1,"")
D22: =IFERROR(VLOOKUP(A22,'MATRICE COMPO'!$A:$H,3,FALSE),"") | E22: =IFERROR(F22+G22+H22,"") | G22: =IF(B22="","",F22*$G$1) | H22: =IFERROR((F22+G22)*$H$1,"")
D23: =IFERROR(VLOOKUP(A23,'MATRICE COMPO'!$A:$H,3,FALSE),"") | E23: =IFERROR(F23+G23+H23,"") | G23: =IF(B23="","",F23*$G$1) | H23: =IFERROR((F23+G23)*$H$1,"")
D24: =IFERROR(VLOOKUP(A24,'MATRICE COMPO'!$A:$H,3,FALSE),"") | E24: =IFERROR(F24+G24+H24,"") | G24: =IF(B24="","",F24*$G$1) | H24: =IFERROR((F24+G24)*$H$1,"")
D25: =IFERROR(VLOOKUP(A25,'MATRICE COMPO'!$A:$H,3,FALSE),"") | E25: =IFERROR(F25+G25+H25,"") | G25: =IF(B25="","",F25*$G$1) | H25: =IFERROR((F25+G25)*$H$1,"")
D26: =IFERROR(VLOOKUP(A26,'MATRICE COMPO'!$A:$H,3,FALSE),"") | E26: =IFERROR(F26+G26+H26,"") | G26: =IF(B26="","",F26*$G$1) | H26: =IFERROR((F26+G26)*$H$1,"")
D27: =IFERROR(VLOOKUP(A27,'MATRICE COMPO'!$A:$H,3,FALSE),"") | E27: =IFERROR(F27+G27+H27,"") | G27: =IF(B27="","",F27*$G$1) | H27: =IFERROR((F27+G27)*$H$1,"")
D28: =IFERROR(VLOOKUP(A28,'MATRICE COMPO'!$A:$H,3,FALSE),"") | E28: =IFERROR(F28+G28+H28,"") | G28: =IF(B28="","",F28*$G$1) | H28: =IFERROR((F28+G28)*$H$1,"")
... D91: =IFERROR(VLOOKUP(A91,'MATRICE COMPO'!$A:$H,3,FALSE),"") | E91: =IFERROR(F91+G91+H91,"") | G91: =IF(B91="","",F91*$G$1) | H91: =IFERROR((F91+G91)*$H$1,"")

Sheet COMPOSITION
A1: Liste déroulante: | B1: COMPOSITION | C1: ID | D1: Unité | E1: PRIX / U | F1: MAT | G1: MO | H1: =GESTION!B4 -> 0.3 | I1: =GESTION!B3 -> 0.1
A2: {=_xlfn.UNIQUE(_xlfn._xlws.FILTER('MATRICE COMPO'!A2:A199,NOT(ISBLANK('MATRICE COMPO'!A2:A199))))} -> Pare-vapeur SD 90 / Structure 145 mm / Laine minérale 150 mm / OSB 12 / Bache de protection provisoire | B2: =IF(A2=0,"",A2) -> Pare-vapeur SD 90 / Structure 145 mm / Laine minérale 150 mm / OSB 12 / Bache de protection provisoire | C2: =IF($B2="","",VLOOKUP($B2,'MATRICE COMPO'!$A:$I,9,FALSE)) -> PE-15 | D2: =IFERROR(VLOOKUP(A2,'MATRICE COMPO'!$A:$H,3,FALSE),"") -> m2 | E2: =IF(B2="","",VLOOKUP(B2,'MATRICE COMPO'!$A:$H,4,FALSE)) -> 83.133938 | F2: =IF(B2="","",VLOOKUP($B2,'MATRICE COMPO'!$A:$H,5,FALSE)) -> 50.215621 | G2: =IF($B2="","",VLOOKUP($B2,'MATRICE COMPO'!$A:$H,6,FALSE)) -> 7.92 | H2: =IF($B2="","",VLOOKUP($B2,'MATRICE COMPO'!$A:$H,7,FALSE)) -> 17.440686 | I2: =IF($B2="","",VLOOKUP($B2,'MATRICE COMPO'!$A:$H,8,FALSE)) -> 7.5576307
A3: Structure 100 mm / OSB 12 / Bache de protection provisoire / Pignon | B3: =IF(A3=0,"",A3) -> Structure 100 mm / OSB 12 / Bache de protection provisoire / Pignon | C3: =IF($B3="","",VLOOKUP($B3,'MATRICE COMPO'!$A:$I,9,FALSE)) -> PEST-10 | D3: =IFERROR(VLOOKUP(A3,'MATRICE COMPO'!$A:$H,3,FALSE),"") -> m2 | E3: =IF(B3="","",VLOOKUP(B3,'MATRICE COMPO'!$A:$H,4,FALSE)) -> 63.852748 | F3: =IF(B3="","",VLOOKUP($B3,'MATRICE COMPO'!$A:$H,5,FALSE)) -> 27.002271 | G3: =IF($B3="","",VLOOKUP($B3,'MATRICE COMPO'!$A:$H,6,FALSE)) -> 17.65 | H3: =IF($B3="","",VLOOKUP($B3,'MATRICE COMPO'!$A:$H,7,FALSE)) -> 13.395681 | I3: =IF($B3="","",VLOOKUP($B3,'MATRICE COMPO'!$A:$H,8,FALSE)) -> 5.8047952
A4: Structure 100 mm / Bardage horizontal cl4 | B4: =IF(A4=0,"",A4) -> Structure 100 mm / Bardage horizontal cl4 | C4: =IF($B4="","",VLOOKUP($B4,'MATRICE COMPO'!$A:$I,9,FALSE)) -> PEST-10-BARDAGE | D4: =IFERROR(VLOOKUP(A4,'MATRICE COMPO'!$A:$H,3,FALSE),"") -> m2 | E4: =IF(B4="","",VLOOKUP(B4,'MATRICE COMPO'!$A:$H,4,FALSE)) -> 61.764948 | F4: =IF(B4="","",VLOOKUP($B4,'MATRICE COMPO'!$A:$H,5,FALSE)) -> 36.342271 | G4: =IF($B4="","",VLOOKUP($B4,'MATRICE COMPO'!$A:$H,6,FALSE)) -> 6.85 | H4: =IF($B4="","",VLOOKUP($B4,'MATRICE COMPO'!$A:$H,7,FALSE)) -> 12.957681 | I4: =IF($B4="","",VLOOKUP($B4,'MATRICE COMPO'!$A:$H,8,FALSE)) -> 5.6149952
A5: Structure 100 mm / Bardage horizontal cl4 / Pignon | B5: =IF(A5=0,"",A5) -> Structure 100 mm / Bardage horizontal cl4 / Pignon | C5: =IF($B5="","",VLOOKUP($B5,'MATRICE COMPO'!$A:$I,9,FALSE)) -> PEST-10-BARDAGE PIGNON | D5: =IFERROR(VLOOKUP(A5,'MATRICE COMPO'!$A:$H,3,FALSE),"") -> m2 | E5: =IF(B5="","",VLOOKUP(B5,'MATRICE COMPO'!$A:$H,4,FALSE)) -> 79.468348 | F5: =IF(B5="","",VLOOKUP($B5,'MATRICE COMPO'!$A:$H,5,FALSE)) -> 36.342271 | G5: =IF($B5="","",VLOOKUP($B5,'MATRICE COMPO'!$A:$H,6,FALSE)) -> 19.23 | H5: =IF($B5="","",VLOOKUP($B5,'MATRICE COMPO'!$A:$H,7,FALSE)) -> 16.671681 | I5: =IF($B5="","",VLOOKUP($B5,'MATRICE COMPO'!$A:$H,8,FALSE)) -> 7.2243952
A6: OSB 22 / Structure PP 260-625 | B6: =IF(A6=0,"",A6) -> OSB 22 / Structure PP 260-625 | C6: =IF($B6="","",VLOOKUP($B6,'MATRICE COMPO'!$A:$I,9,FALSE)) -> PP-625 | D6: =IFERROR(VLOOKUP(A6,'MATRICE COMPO'!$A:$H,3,FALSE),"") -> m2 | E6: =IF(B6="","",VLOOKUP(B6,'MATRICE COMPO'!$A:$H,4,FALSE)) -> 62.557923 | F6: =IF(B6="","",VLOOKUP($B6,'MATRICE COMPO'!$A:$H,5,FALSE)) -> 36.636799 | G6: =IF($B6="","",VLOOKUP($B6,'MATRICE COMPO'!$A:$H,6,FALSE)) -> 7.11 | H6: =IF($B6="","",VLOOKUP($B6,'MATRICE COMPO'!$A:$H,7,FALSE)) -> 13.12404 | I6: =IF($B6="","",VLOOKUP($B6,'MATRICE COMPO'!$A:$H,8,FALSE)) -> 5.6870839
A7: OSB 22 / Structure PP 260-313 | B7: =IF(A7=0,"",A7) -> OSB 22 / Structure PP 260-313 | C7: =IF($B7="","",VLOOKUP($B7,'MATRICE COMPO'!$A:$I,9,FALSE)) -> PP-313 | D7: =IFERROR(VLOOKUP(A7,'MATRICE COMPO'!$A:$H,3,FALSE),"") -> m2 | E7: =IF(B7="","",VLOOKUP(B7,'MATRICE COMPO'!$A:$H,4,FALSE)) -> 81.405737 | F7: =IF(B7="","",VLOOKUP($B7,'MATRICE COMPO'!$A:$H,5,FALSE)) -> 46.887089 | G7: =IF($B7="","",VLOOKUP($B7,'MATRICE COMPO'!$A:$H,6,FALSE)) -> 10.04 | H7: =IF($B7="","",VLOOKUP($B7,'MATRICE COMPO'!$A:$H,7,FALSE)) -> 17.078127 | I7: =IF($B7="","",VLOOKUP($B7,'MATRICE COMPO'!$A:$H,8,FALSE)) -> 7.4005216
B8: =IF(A8=0,"",A8) | C8: =IF($B8="","",VLOOKUP($B8,'MATRICE COMPO'!$A:$I,9,FALSE)) | D8: =IFERROR(VLOOKUP(A8,'MATRICE COMPO'!$A:$H,3,FALSE),"") | E8: =IF(B8="","",VLOOKUP(B8,'MATRICE COMPO'!$A:$H,4,FALSE)) | F8: =IF(B8="","",VLOOKUP($B8,'MATRICE COMPO'!$A:$H,5,FALSE)) | G8: =IF($B8="","",VLOOKUP($B8,'MATRICE COMPO'!$A:$H,6,FALSE)) | H8: =IF($B8="","",VLOOKUP($B8,'MATRICE COMPO'!$A:$H,7,FALSE)) | I8: =IF($B8="","",VLOOKUP($B8,'MATRICE COMPO'!$A:$H,8,FALSE))
B9: =IF(A9=0,"",A9) | C9: =IF($B9="","",VLOOKUP($B9,'MATRICE COMPO'!$A:$I,9,FALSE)) | D9: =IFERROR(VLOOKUP(A9,'MATRICE COMPO'!$A:$H,3,FALSE),"") | E9: =IF(B9="","",VLOOKUP(B9,'MATRICE COMPO'!$A:$H,4,FALSE)) | F9: =IF(B9="","",VLOOKUP($B9,'MATRICE COMPO'!$A:$H,5,FALSE)) | G9: =IF($B9="","",VLOOKUP($B9,'MATRICE COMPO'!$A:$H,6,FALSE)) | H9: =IF($B9="","",VLOOKUP($B9,'MATRICE COMPO'!$A:$H,7,FALSE)) | I9: =IF($B9="","",VLOOKUP($B9,'MATRICE COMPO'!$A:$H,8,FALSE))
B10: =IF(A10=0,"",A10) | C10: =IF($B10="","",VLOOKUP($B10,'MATRICE COMPO'!$A:$I,9,FALSE)) | D10: =IFERROR(VLOOKUP(A10,'MATRICE COMPO'!$A:$H,3,FALSE),"") | E10: =IF(B10="","",VLOOKUP(B10,'MATRICE COMPO'!$A:$H,4,FALSE)) | F10: =IF(B10="","",VLOOKUP($B10,'MATRICE COMPO'!$A:$H,5,FALSE)) | G10: =IF($B10="","",VLOOKUP($B10,'MATRICE COMPO'!$A:$H,6,FALSE)) | H10: =IF($B10="","",VLOOKUP($B10,'MATRICE COMPO'!$A:$H,7,FALSE)) | I10: =IF($B10="","",VLOOKUP($B10,'MATRICE COMPO'!$A:$H,8,FALSE))
B11: =IF(A11=0,"",A11) | C11: =IF($B11="","",VLOOKUP($B11,'MATRICE COMPO'!$A:$I,9,FALSE)) | D11: =IFERROR(VLOOKUP(A11,'MATRICE COMPO'!$A:$H,3,FALSE),"") | E11: =IF(B11="","",VLOOKUP(B11,'MATRICE COMPO'!$A:$H,4,FALSE)) | F11: =IF(B11="","",VLOOKUP($B11,'MATRICE COMPO'!$A:$H,5,FALSE)) | G11: =IF($B11="","",VLOOKUP($B11,'MATRICE COMPO'!$A:$H,6,FALSE)) | H11: =IF($B11="","",VLOOKUP($B11,'MATRICE COMPO'!$A:$H,7,FALSE)) | I11: =IF($B11="","",VLOOKUP($B11,'MATRICE COMPO'!$A:$H,8,FALSE))
B12: =IF(A12=0,"",A12) | C12: =IF($B12="","",VLOOKUP($B12,'MATRICE COMPO'!$A:$I,9,FALSE)) | D12: =IFERROR(VLOOKUP(A12,'MATRICE COMPO'!$A:$H,3,FALSE),"") | E12: =IF(B12="","",VLOOKUP(B12,'MATRICE COMPO'!$A:$H,4,FALSE)) | F12: =IF(B12="","",VLOOKUP($B12,'MATRICE COMPO'!$A:$H,5,FALSE)) | G12: =IF($B12="","",VLOOKUP($B12,'MATRICE COMPO'!$A:$H,6,FALSE)) | H12: =IF($B12="","",VLOOKUP($B12,'MATRICE COMPO'!$A:$H,7,FALSE)) | I12: =IF($B12="","",VLOOKUP($B12,'MATRICE COMPO'!$A:$H,8,FALSE))
B13: =IF(A13=0,"",A13) | C13: =IF($B13="","",VLOOKUP($B13,'MATRICE COMPO'!$A:$I,9,FALSE)) | D13: =IFERROR(VLOOKUP(A13,'MATRICE COMPO'!$A:$H,3,FALSE),"") | E13: =IF(B13="","",VLOOKUP(B13,'MATRICE COMPO'!$A:$H,4,FALSE)) | F13: =IF(B13="","",VLOOKUP($B13,'MATRICE COMPO'!$A:$H,5,FALSE)) | G13: =IF($B13="","",VLOOKUP($B13,'MATRICE COMPO'!$A:$H,6,FALSE)) | H13: =IF($B13="","",VLOOKUP($B13,'MATRICE COMPO'!$A:$H,7,FALSE)) | I13: =IF($B13="","",VLOOKUP($B13,'MATRICE COMPO'!$A:$H,8,FALSE))
B14: =IF(A14=0,"",A14) | C14: =IF($B14="","",VLOOKUP($B14,'MATRICE COMPO'!$A:$I,9,FALSE)) | D14: =IFERROR(VLOOKUP(A14,'MATRICE COMPO'!$A:$H,3,FALSE),"") | E14: =IF(B14="","",VLOOKUP(B14,'MATRICE COMPO'!$A:$H,4,FALSE)) | F14: =IF(B14="","",VLOOKUP($B14,'MATRICE COMPO'!$A:$H,5,FALSE)) | G14: =IF($B14="","",VLOOKUP($B14,'MATRICE COMPO'!$A:$H,6,FALSE)) | H14: =IF($B14="","",VLOOKUP($B14,'MATRICE COMPO'!$A:$H,7,FALSE)) | I14: =IF($B14="","",VLOOKUP($B14,'MATRICE COMPO'!$A:$H,8,FALSE))
B15: =IF(A15=0,"",A15) | C15: =IF($B15="","",VLOOKUP($B15,'MATRICE COMPO'!$A:$I,9,FALSE)) | D15: =IFERROR(VLOOKUP(A15,'MATRICE COMPO'!$A:$H,3,FALSE),"") | E15: =IF(B15="","",VLOOKUP(B15,'MATRICE COMPO'!$A:$H,4,FALSE)) | F15: =IF(B15="","",VLOOKUP($B15,'MATRICE COMPO'!$A:$H,5,FALSE)) | G15: =IF($B15="","",VLOOKUP($B15,'MATRICE COMPO'!$A:$H,6,FALSE)) | H15: =IF($B15="","",VLOOKUP($B15,'MATRICE COMPO'!$A:$H,7,FALSE)) | I15: =IF($B15="","",VLOOKUP($B15,'MATRICE COMPO'!$A:$H,8,FALSE))
B16: =IF(A16=0,"",A16) | C16: =IF($B16="","",VLOOKUP($B16,'MATRICE COMPO'!$A:$I,9,FALSE)) | D16: =IFERROR(VLOOKUP(A16,'MATRICE COMPO'!$A:$H,3,FALSE),"") | E16: =IF(B16="","",VLOOKUP(B16,'MATRICE COMPO'!$A:$H,4,FALSE)) | F16: =IF(B16="","",VLOOKUP($B16,'MATRICE COMPO'!$A:$H,5,FALSE)) | G16: =IF($B16="","",VLOOKUP($B16,'MATRICE COMPO'!$A:$H,6,FALSE)) | H16: =IF($B16="","",VLOOKUP($B16,'MATRICE COMPO'!$A:$H,7,FALSE)) | I16: =IF($B16="","",VLOOKUP($B16,'MATRICE COMPO'!$A:$H,8,FALSE))
B17: =IF(A17=0,"",A17) | C17: =IF($B17="","",VLOOKUP($B17,'MATRICE COMPO'!$A:$I,9,FALSE)) | D17: =IFERROR(VLOOKUP(A17,'MATRICE COMPO'!$A:$H,3,FALSE),"") | E17: =IF(B17="","",VLOOKUP(B17,'MATRICE COMPO'!$A:$H,4,FALSE)) | F17: =IF(B17="","",VLOOKUP($B17,'MATRICE COMPO'!$A:$H,5,FALSE)) | G17: =IF($B17="","",VLOOKUP($B17,'MATRICE COMPO'!$A:$H,6,FALSE)) | H17: =IF($B17="","",VLOOKUP($B17,'MATRICE COMPO'!$A:$H,7,FALSE)) | I17: =IF($B17="","",VLOOKUP($B17,'MATRICE COMPO'!$A:$H,8,FALSE))
B18: =IF(A18=0,"",A18) | C18: =IF($B18="","",VLOOKUP($B18,'MATRICE COMPO'!$A:$I,9,FALSE)) | D18: =IFERROR(VLOOKUP(A18,'MATRICE COMPO'!$A:$H,3,FALSE),"") | E18: =IF(B18="","",VLOOKUP(B18,'MATRICE COMPO'!$A:$H,4,FALSE)) | F18: =IF(B18="","",VLOOKUP($B18,'MATRICE COMPO'!$A:$H,5,FALSE)) | G18: =IF($B18="","",VLOOKUP($B18,'MATRICE COMPO'!$A:$H,6,FALSE)) | H18: =IF($B18="","",VLOOKUP($B18,'MATRICE COMPO'!$A:$H,7,FALSE)) | I18: =IF($B18="","",VLOOKUP($B18,'MATRICE COMPO'!$A:$H,8,FALSE))
B19: =IF(A19=0,"",A19) | C19: =IF($B19="","",VLOOKUP($B19,'MATRICE COMPO'!$A:$I,9,FALSE)) | D19: =IFERROR(VLOOKUP(A19,'MATRICE COMPO'!$A:$H,3,FALSE),"") | E19: =IF(B19="","",VLOOKUP(B19,'MATRICE COMPO'!$A:$H,4,FALSE)) | F19: =IF(B19="","",VLOOKUP($B19,'MATRICE COMPO'!$A:$H,5,FALSE)) | G19: =IF($B19="","",VLOOKUP($B19,'MATRICE COMPO'!$A:$H,6,FALSE)) | H19: =IF($B19="","",VLOOKUP($B19,'MATRICE COMPO'!$A:$H,7,FALSE)) | I19: =IF($B19="","",VLOOKUP($B19,'MATRICE COMPO'!$A:$H,8,FALSE))
... B91: =IF(A91=0,"",A91) | C91: =IF($B91="","",VLOOKUP($B91,'MATRICE COMPO'!$A:$I,9,FALSE)) | D91: =IFERROR(VLOOKUP(A91,'MATRICE COMPO'!$A:$H,3,FALSE),"") | E91: =IF(B91="","",VLOOKUP(B91,'MATRICE COMPO'!$A:$H,4,FALSE)) | F91: =IF(B91="","",VLOOKUP($B91,'MATRICE COMPO'!$A:$H,5,FALSE)) | G91: =IF($B91="","",VLOOKUP($B91,'MATRICE COMPO'!$A:$H,6,FALSE)) | H91: =IF($B91="","",VLOOKUP($B91,'MATRICE COMPO'!$A:$H,7,FALSE)) | I91: =IF($B91="","",VLOOKUP($B91,'MATRICE COMPO'!$A:$H,8,FALSE))

Sheet MATRICE COMPO
A1: COMPOSITION | C1: Unité | D1: PRIX | E1: MAT | F1: MO | G1: =GESTION!$B$4 -> 0.3 | H1: =GESTION!$B$3 -> 0.1 | I1: ID | K1: Valeur | L1: MAT | N1: MO | P1: Marge | R1: FG
A2: =B2 -> Pare-vapeur SD 90 / Structure 145 mm / Laine minérale 150 mm / OSB 12 / Bache de protection provisoire | B2: =CONCATENATE(B3,IF(B4="",""," / "),B4,IF(B5="",""," / "),B5,IF(B6="",""," / "),B6,IF(B7="",""," / "),B7,IF(B8="",""," / "),B8,IF(B9="",""," / "),B9,B9,IF(B10="",""," / "),B10,IF(B11="",""," / "),B11,IF(B12="",""," / "),B12) -> Pare-vapeur SD 90 / Structure 145 mm / Laine minérale 150 mm / OSB 12 / Bache de protection provisoire | C2: =C3 -> m2 | D2: =IF(SUM(E2:H2)=0,0,SUM(E2:H2)) -> 83.133938 | E2: =SUM(E3:E12) -> 50.215621 | F2: =SUM(F3:F12) -> 7.92 | G2: =SUM(G3:G12) -> 17.440686 | H2: =SUM(H3:H12) -> 7.5576307 | I2: PE-15 | J2: =716+757 -> 1473 | K2: =ROUNDUP(D2,0)*J2 -> 123732 | L2: =ROUNDUP(J2*E2,0) -> 73968 | M2: =L2/K2 -> 0.59780817 | N2: =ROUNDUP(J2*F2,0) -> 11667 | O2: =N2/K2 -> 0.094292503 | P2: =ROUNDUP(J2*G2,0) -> 25691 | Q2: =P2/K2 -> 0.20763424 | R2: =ROUNDUP(J2*H2,0) -> 11133 | S2: =R2/K2 -> 0.089976724
B3: Pare-vapeur SD 90 | C3: =IFERROR(IF(ISBLANK(VLOOKUP($B3,ARTICLE!$B$2:$J$200,3,FALSE)),"",VLOOKUP($B3,ARTICLE!$B$2:$J$200,3,FALSE)),"") -> m2 | D3: =IFERROR(IF(ISBLANK(VLOOKUP($B3,ARTICLE!$B$2:$J$200,4,FALSE)),"",VLOOKUP($B3,ARTICLE!$B$2:$J$200,4,FALSE)),"") -> 3.8181 | E3: =IFERROR(IF(ISBLANK(VLOOKUP($B3,ARTICLE!$B$2:$J$200,5,FALSE)),"",VLOOKUP($B3,ARTICLE!$B$2:$J$200,5,FALSE)),"") -> 2.06 | F3: =IFERROR(IF(ISBLANK(VLOOKUP($B3,ARTICLE!$B$2:$J$200,6,FALSE)),"",VLOOKUP($B3,ARTICLE!$B$2:$J$200,6,FALSE)),"") -> 0.61 | G3: =IFERROR(IF(ISBLANK(VLOOKUP($B3,ARTICLE!$B$2:$J$200,7,FALSE)),"",VLOOKUP($B3,ARTICLE!$B$2:$J$200,7,FALSE)),"") -> 0.801 | H3: =IFERROR(IF(ISBLANK(VLOOKUP($B3,ARTICLE!$B$2:$J$200,8,FALSE)),"",VLOOKUP($B3,ARTICLE!$B$2:$J$200,8,FALSE)),"") -> 0.3471
B4: Structure 145 mm | C4: =IFERROR(IF(ISBLANK(VLOOKUP($B4,ARTICLE!$B$2:$J$200,3,FALSE)),"",VLOOKUP($B4,ARTICLE!$B$2:$J$200,3,FALSE)),"") -> m2 | D4: =IFERROR(IF(ISBLANK(VLOOKUP($B4,ARTICLE!$B$2:$J$200,4,FALSE)),"",VLOOKUP($B4,ARTICLE!$B$2:$J$200,4,FALSE)),"") -> 48.442138 | E4: =IFERROR(IF(ISBLANK(VLOOKUP($B4,ARTICLE!$B$2:$J$200,5,FALSE)),"",VLOOKUP($B4,ARTICLE!$B$2:$J$200,5,FALSE)),"") -> 29.445621 | F4: =IFERROR(IF(ISBLANK(VLOOKUP($B4,ARTICLE!$B$2:$J$200,6,FALSE)),"",VLOOKUP($B4,ARTICLE!$B$2:$J$200,6,FALSE)),"") -> 4.43 | G4: =IFERROR(IF(ISBLANK(VLOOKUP($B4,ARTICLE!$B$2:$J$200,7,FALSE)),"",VLOOKUP($B4,ARTICLE!$B$2:$J$200,7,FALSE)),"") -> 10.162686 | H4: =IFERROR(IF(ISBLANK(VLOOKUP($B4,ARTICLE!$B$2:$J$200,8,FALSE)),"",VLOOKUP($B4,ARTICLE!$B$2:$J$200,8,FALSE)),"") -> 4.4038307
B5: Laine minérale 150 mm | C5: =IFERROR(IF(ISBLANK(VLOOKUP($B5,ARTICLE!$B$2:$J$200,3,FALSE)),"",VLOOKUP($B5,ARTICLE!$B$2:$J$200,3,FALSE)),"") -> m2 | D5: =IFERROR(IF(ISBLANK(VLOOKUP($B5,ARTICLE!$B$2:$J$200,4,FALSE)),"",VLOOKUP($B5,ARTICLE!$B$2:$J$200,4,FALSE)),"") -> 17.1171 | E5: =IFERROR(IF(ISBLANK(VLOOKUP($B5,ARTICLE!$B$2:$J$200,5,FALSE)),"",VLOOKUP($B5,ARTICLE!$B$2:$J$200,5,FALSE)),"") -> 10.53 | F5: =IFERROR(IF(ISBLANK(VLOOKUP($B5,ARTICLE!$B$2:$J$200,6,FALSE)),"",VLOOKUP($B5,ARTICLE!$B$2:$J$200,6,FALSE)),"") -> 1.44 | G5: =IFERROR(IF(ISBLANK(VLOOKUP($B5,ARTICLE!$B$2:$J$200,7,FALSE)),"",VLOOKUP($B5,ARTICLE!$B$2:$J$200,7,FALSE)),"") -> 3.591 | H5: =IFERROR(IF(ISBLANK(VLOOKUP($B5,ARTICLE!$B$2:$J$200,8,FALSE)),"",VLOOKUP($B5,ARTICLE!$B$2:$J$200,8,FALSE)),"") -> 1.5561
B6: OSB 12 | C6: =IFERROR(IF(ISBLANK(VLOOKUP($B6,ARTICLE!$B$2:$J$200,3,FALSE)),"",VLOOKUP($B6,ARTICLE!$B$2:$J$200,3,FALSE)),"") -> m2 | D6: =IFERROR(IF(ISBLANK(VLOOKUP($B6,ARTICLE!$B$2:$J$200,4,FALSE)),"",VLOOKUP($B6,ARTICLE!$B$2:$J$200,4,FALSE)),"") -> 11.8404 | E6: =IFERROR(IF(ISBLANK(VLOOKUP($B6,ARTICLE!$B$2:$J$200,5,FALSE)),"",VLOOKUP($B6,ARTICLE!$B$2:$J$200,5,FALSE)),"") -> 7.45 | F6: =IFERROR(IF(ISBLANK(VLOOKUP($B6,ARTICLE!$B$2:$J$200,6,FALSE)),"",VLOOKUP($B6,ARTICLE!$B$2:$J$200,6,FALSE)),"") -> 0.83 | G6: =IFERROR(IF(ISBLANK(VLOOKUP($B6,ARTICLE!$B$2:$J$200,7,FALSE)),"",VLOOKUP($B6,ARTICLE!$B$2:$J$200,7,FALSE)),"") -> 2.484 | H6: =IFERROR(IF(ISBLANK(VLOOKUP($B6,ARTICLE!$B$2:$J$200,8,FALSE)),"",VLOOKUP($B6,ARTICLE!$B$2:$J$200,8,FALSE)),"") -> 1.0764
B7: Bache de protection provisoire | C7: =IFERROR(IF(ISBLANK(VLOOKUP($B7,ARTICLE!$B$2:$J$200,3,FALSE)),"",VLOOKUP($B7,ARTICLE!$B$2:$J$200,3,FALSE)),"") -> m2 | D7: =IFERROR(IF(ISBLANK(VLOOKUP($B7,ARTICLE!$B$2:$J$200,4,FALSE)),"",VLOOKUP($B7,ARTICLE!$B$2:$J$200,4,FALSE)),"") -> 1.9162 | E7: =IFERROR(IF(ISBLANK(VLOOKUP($B7,ARTICLE!$B$2:$J$200,5,FALSE)),"",VLOOKUP($B7,ARTICLE!$B$2:$J$200,5,FALSE)),"") -> 0.73 | F7: =IFERROR(IF(ISBLANK(VLOOKUP($B7,ARTICLE!$B$2:$J$200,6,FALSE)),"",VLOOKUP($B7,ARTICLE!$B$2:$J$200,6,FALSE)),"") -> 0.61 | G7: =IFERROR(IF(ISBLANK(VLOOKUP($B7,ARTICLE!$B$2:$J$200,7,FALSE)),"",VLOOKUP($B7,ARTICLE!$B$2:$J$200,7,FALSE)),"") -> 0.402 | H7: =IFERROR(IF(ISBLANK(VLOOKUP($B7,ARTICLE!$B$2:$J$200,8,FALSE)),"",VLOOKUP($B7,ARTICLE!$B$2:$J$200,8,FALSE)),"") -> 0.1742
C8: =IFERROR(IF(ISBLANK(VLOOKUP($B8,ARTICLE!$B$2:$J$200,3,FALSE)),"",VLOOKUP($B8,ARTICLE!$B$2:$J$200,3,FALSE)),"") | D8: =IFERROR(IF(ISBLANK(VLOOKUP($B8,ARTICLE!$B$2:$J$200,4,FALSE)),"",VLOOKUP($B8,ARTICLE!$B$2:$J$200,4,FALSE)),"") | E8: =IFERROR(IF(ISBLANK(VLOOKUP($B8,ARTICLE!$B$2:$J$200,5,FALSE)),"",VLOOKUP($B8,ARTICLE!$B$2:$J$200,5,FALSE)),"") | F8: =IFERROR(IF(ISBLANK(VLOOKUP($B8,ARTICLE!$B$2:$J$200,6,FALSE)),"",VLOOKUP($B8,ARTICLE!$B$2:$J$200,6,FALSE)),"") | G8: =IFERROR(IF(ISBLANK(VLOOKUP($B8,ARTICLE!$B$2:$J$200,7,FALSE)),"",VLOOKUP($B8,ARTICLE!$B$2:$J$200,7,FALSE)),"") | H8: =IFERROR(IF(ISBLANK(VLOOKUP($B8,ARTICLE!$B$2:$J$200,8,FALSE)),"",VLOOKUP($B8,ARTICLE!$B$2:$J$200,8,FALSE)),"")
C9: =IFERROR(IF(ISBLANK(VLOOKUP($B9,ARTICLE!$B$2:$J$200,3,FALSE)),"",VLOOKUP($B9,ARTICLE!$B$2:$J$200,3,FALSE)),"") | D9: =IFERROR(IF(ISBLANK(VLOOKUP($B9,ARTICLE!$B$2:$J$200,4,FALSE)),"",VLOOKUP($B9,ARTICLE!$B$2:$J$200,4,FALSE)),"") | E9: =IFERROR(IF(ISBLANK(VLOOKUP($B9,ARTICLE!$B$2:$J$200,5,FALSE)),"",VLOOKUP($B9,ARTICLE!$B$2:$J$200,5,FALSE)),"") | F9: =IFERROR(IF(ISBLANK(VLOOKUP($B9,ARTICLE!$B$2:$J$200,6,FALSE)),"",VLOOKUP($B9,ARTICLE!$B$2:$J$200,6,FALSE)),"") | G9: =IFERROR(IF(ISBLANK(VLOOKUP($B9,ARTICLE!$B$2:$J$200,7,FALSE)),"",VLOOKUP($B9,ARTICLE!$B$2:$J$200,7,FALSE)),"") | H9: =IFERROR(IF(ISBLANK(VLOOKUP($B9,ARTICLE!$B$2:$J$200,8,FALSE)),"",VLOOKUP($B9,ARTICLE!$B$2:$J$200,8,FALSE)),"")
C10: =IFERROR(IF(ISBLANK(VLOOKUP($B10,ARTICLE!$B$2:$J$200,3,FALSE)),"",VLOOKUP($B10,ARTICLE!$B$2:$J$200,3,FALSE)),"") | D10: =IFERROR(IF(ISBLANK(VLOOKUP($B10,ARTICLE!$B$2:$J$200,4,FALSE)),"",VLOOKUP($B10,ARTICLE!$B$2:$J$200,4,FALSE)),"") | E10: =IFERROR(IF(ISBLANK(VLOOKUP($B10,ARTICLE!$B$2:$J$200,5,FALSE)),"",VLOOKUP($B10,ARTICLE!$B$2:$J$200,5,FALSE)),"") | F10: =IFERROR(IF(ISBLANK(VLOOKUP($B10,ARTICLE!$B$2:$J$200,6,FALSE)),"",VLOOKUP($B10,ARTICLE!$B$2:$J$200,6,FALSE)),"") | G10: =IFERROR(IF(ISBLANK(VLOOKUP($B10,ARTICLE!$B$2:$J$200,7,FALSE)),"",VLOOKUP($B10,ARTICLE!$B$2:$J$200,7,FALSE)),"") | H10: =IFERROR(IF(ISBLANK(VLOOKUP($B10,ARTICLE!$B$2:$J$200,8,FALSE)),"",VLOOKUP($B10,ARTICLE!$B$2:$J$200,8,FALSE)),"")
C11: =IFERROR(IF(ISBLANK(VLOOKUP($B11,ARTICLE!$B$2:$J$200,3,FALSE)),"",VLOOKUP($B11,ARTICLE!$B$2:$J$200,3,FALSE)),"") | D11: =IFERROR(IF(ISBLANK(VLOOKUP($B11,ARTICLE!$B$2:$J$200,4,FALSE)),"",VLOOKUP($B11,ARTICLE!$B$2:$J$200,4,FALSE)),"") | E11: =IFERROR(IF(ISBLANK(VLOOKUP($B11,ARTICLE!$B$2:$J$200,5,FALSE)),"",VLOOKUP($B11,ARTICLE!$B$2:$J$200,5,FALSE)),"") | F11: =IFERROR(IF(ISBLANK(VLOOKUP($B11,ARTICLE!$B$2:$J$200,6,FALSE)),"",VLOOKUP($B11,ARTICLE!$B$2:$J$200,6,FALSE)),"") | G11: =IFERROR(IF(ISBLANK(VLOOKUP($B11,ARTICLE!$B$2:$J$200,7,FALSE)),"",VLOOKUP($B11,ARTICLE!$B$2:$J$200,7,FALSE)),"") | H11: =IFERROR(IF(ISBLANK(VLOOKUP($B11,ARTICLE!$B$2:$J$200,8,FALSE)),"",VLOOKUP($B11,ARTICLE!$B$2:$J$200,8,FALSE)),"")
C12: =IFERROR(IF(ISBLANK(VLOOKUP($B12,ARTICLE!$B$2:$J$200,3,FALSE)),"",VLOOKUP($B12,ARTICLE!$B$2:$J$200,3,FALSE)),"") | D12: =IFERROR(IF(ISBLANK(VLOOKUP($B12,ARTICLE!$B$2:$J$200,4,FALSE)),"",VLOOKUP($B12,ARTICLE!$B$2:$J$200,4,FALSE)),"") | E12: =IFERROR(IF(ISBLANK(VLOOKUP($B12,ARTICLE!$B$2:$J$200,5,FALSE)),"",VLOOKUP($B12,ARTICLE!$B$2:$J$200,5,FALSE)),"") | F12: =IFERROR(IF(ISBLANK(VLOOKUP($B12,ARTICLE!$B$2:$J$200,6,FALSE)),"",VLOOKUP($B12,ARTICLE!$B$2:$J$200,6,FALSE)),"") | G12: =IFERROR(IF(ISBLANK(VLOOKUP($B12,ARTICLE!$B$2:$J$200,7,FALSE)),"",VLOOKUP($B12,ARTICLE!$B$2:$J$200,7,FALSE)),"") | H12: =IFERROR(IF(ISBLANK(VLOOKUP($B12,ARTICLE!$B$2:$J$200,8,FALSE)),"",VLOOKUP($B12,ARTICLE!$B$2:$J$200,8,FALSE)),"")
A13: =B13 -> Structure 100 mm / OSB 12 / Bache de protection provisoire / Pignon | B13: =CONCATENATE(B14,IF(B15="",""," / "),B15,IF(B16="",""," / "),B16,IF(B17="",""," / "),B17,IF(B18="",""," / "),B18,IF(B19="",""," / "),B19,IF(B20="",""," / "),B20,B20,IF(B21="",""," / "),B21) -> Structure 100 mm / OSB 12 / Bache de protection provisoire / Pignon | C13: =C14 -> m2 | D13: =IF(SUM(E13:H13)=0,0,SUM(E13:H13)) -> 63.852748 | E13: =SUM(E14:E23) -> 27.002271 | F13: =SUM(F14:F23) -> 17.65 | G13: =SUM(G14:G23) -> 13.395681 | H13: =SUM(H14:H23) -> 5.8047952 | I13: PEST-10 | J13: =31+46 -> 77 | K13: =ROUNDUP(D13,0)*J13 -> 4928 | L13: =ROUNDUP(J13*E13,0) -> 2080 | M13: =L13/K13 -> 0.42207792 | N13: =ROUNDUP(J13*F13,0) -> 1360 | O13: =N13/K13 -> 0.27597403 | P13: =ROUNDUP(J13*G13,0) -> 1032 | Q13: =P13/K13 -> 0.20941558 | R13: =ROUNDUP(J13*H13,0) -> 447 | S13: =R13/K13 -> 0.090706169
B14: Structure 100 mm | C14: =IFERROR(IF(ISBLANK(VLOOKUP($B14,ARTICLE!$B$2:$J$200,3,FALSE)),"",VLOOKUP($B14,ARTICLE!$B$2:$J$200,3,FALSE)),"") -> m2 | D14: =IFERROR(IF(ISBLANK(VLOOKUP($B14,ARTICLE!$B$2:$J$200,4,FALSE)),"",VLOOKUP($B14,ARTICLE!$B$2:$J$200,4,FALSE)),"") -> 32.392748 | E14: =IFERROR(IF(ISBLANK(VLOOKUP($B14,ARTICLE!$B$2:$J$200,5,FALSE)),"",VLOOKUP($B14,ARTICLE!$B$2:$J$200,5,FALSE)),"") -> 18.822271 | F14: =IFERROR(IF(ISBLANK(VLOOKUP($B14,ARTICLE!$B$2:$J$200,6,FALSE)),"",VLOOKUP($B14,ARTICLE!$B$2:$J$200,6,FALSE)),"") -> 3.83 | G14: =IFERROR(IF(ISBLANK(VLOOKUP($B14,ARTICLE!$B$2:$J$200,7,FALSE)),"",VLOOKUP($B14,ARTICLE!$B$2:$J$200,7,FALSE)),"") -> 6.7956813 | H14: =IFERROR(IF(ISBLANK(VLOOKUP($B14,ARTICLE!$B$2:$J$200,8,FALSE)),"",VLOOKUP($B14,ARTICLE!$B$2:$J$200,8,FALSE)),"") -> 2.9447952
B15: OSB 12 | C15: =IFERROR(IF(ISBLANK(VLOOKUP($B15,ARTICLE!$B$2:$J$200,3,FALSE)),"",VLOOKUP($B15,ARTICLE!$B$2:$J$200,3,FALSE)),"") -> m2 | D15: =IFERROR(IF(ISBLANK(VLOOKUP($B15,ARTICLE!$B$2:$J$200,4,FALSE)),"",VLOOKUP($B15,ARTICLE!$B$2:$J$200,4,FALSE)),"") -> 11.8404 | E15: =IFERROR(IF(ISBLANK(VLOOKUP($B15,ARTICLE!$B$2:$J$200,5,FALSE)),"",VLOOKUP($B15,ARTICLE!$B$2:$J$200,5,FALSE)),"") -> 7.45 | F15: =IFERROR(IF(ISBLANK(VLOOKUP($B15,ARTICLE!$B$2:$J$200,6,FALSE)),"",VLOOKUP($B15,ARTICLE!$B$2:$J$200,6,FALSE)),"") -> 0.83 | G15: =IFERROR(IF(ISBLANK(VLOOKUP($B15,ARTICLE!$B$2:$J$200,7,FALSE)),"",VLOOKUP($B15,ARTICLE!$B$2:$J$200,7,FALSE)),"") -> 2.484 | H15: =IFERROR(IF(ISBLANK(VLOOKUP($B15,ARTICLE!$B$2:$J$200,8,FALSE)),"",VLOOKUP($B15,ARTICLE!$B$2:$J$200,8,FALSE)),"") -> 1.0764
B16: Bache de protection provisoire | C16: =IFERROR(IF(ISBLANK(VLOOKUP($B16,ARTICLE!$B$2:$J$200,3,FALSE)),"",VLOOKUP($B16,ARTICLE!$B$2:$J$200,3,FALSE)),"") -> m2 | D16: =IFERROR(IF(ISBLANK(VLOOKUP($B16,ARTICLE!$B$2:$J$200,4,FALSE)),"",VLOOKUP($B16,ARTICLE!$B$2:$J$200,4,FALSE)),"") -> 1.9162 | E16: =IFERROR(IF(ISBLANK(VLOOKUP($B16,ARTICLE!$B$2:$J$200,5,FALSE)),"",VLOOKUP($B16,ARTICLE!$B$2:$J$200,5,FALSE)),"") -> 0.73 | F16: =IFERROR(IF(ISBLANK(VLOOKUP($B16,ARTICLE!$B$2:$J$200,6,FALSE)),"",VLOOKUP($B16,ARTICLE!$B$2:$J$200,6,FALSE)),"") -> 0.61 | G16: =IFERROR(IF(ISBLANK(VLOOKUP($B16,ARTICLE!$B$2:$J$200,7,FALSE)),"",VLOOKUP($B16,ARTICLE!$B$2:$J$200,7,FALSE)),"") -> 0.402 | H16: =IFERROR(IF(ISBLANK(VLOOKUP($B16,ARTICLE!$B$2:$J$200,8,FALSE)),"",VLOOKUP($B16,ARTICLE!$B$2:$J$200,8,FALSE)),"") -> 0.1742
B17: Pignon | C17: =IFERROR(IF(ISBLANK(VLOOKUP($B17,ARTICLE!$B$2:$J$200,3,FALSE)),"",VLOOKUP($B17,ARTICLE!$B$2:$J$200,3,FALSE)),"") -> m2 | D17: =IFERROR(IF(ISBLANK(VLOOKUP($B17,ARTICLE!$B$2:$J$200,4,FALSE)),"",VLOOKUP($B17,ARTICLE!$B$2:$J$200,4,FALSE)),"") -> 17.7034 | E17: =IFERROR(IF(ISBLANK(VLOOKUP($B17,ARTICLE!$B$2:$J$200,5,FALSE)),"",VLOOKUP($B17,ARTICLE!$B$2:$J$200,5,FALSE)),"") -> 0 | F17: =IFERROR(IF(ISBLANK(VLOOKUP($B17,ARTICLE!$B$2:$J$200,6,FALSE)),"",VLOOKUP($B17,ARTICLE!$B$2:$J$200,6,FALSE)),"") -> 12.38 | G17: =IFERROR(IF(ISBLANK(VLOOKUP($B17,ARTICLE!$B$2:$J$200,7,FALSE)),"",VLOOKUP($B17,ARTICLE!$B$2:$J$200,7,FALSE)),"") -> 3.714 | H17: =IFERROR(IF(ISBLANK(VLOOKUP($B17,ARTICLE!$B$2:$J$200,8,FALSE)),"",VLOOKUP($B17,ARTICLE!$B$2:$J$200,8,FALSE)),"") -> 1.6094
C18: =IFERROR(IF(ISBLANK(VLOOKUP($B18,ARTICLE!$B$2:$J$200,3,FALSE)),"",VLOOKUP($B18,ARTICLE!$B$2:$J$200,3,FALSE)),"") | D18: =IFERROR(IF(ISBLANK(VLOOKUP($B18,ARTICLE!$B$2:$J$200,4,FALSE)),"",VLOOKUP($B18,ARTICLE!$B$2:$J$200,4,FALSE)),"") | E18: =IFERROR(IF(ISBLANK(VLOOKUP($B18,ARTICLE!$B$2:$J$200,5,FALSE)),"",VLOOKUP($B18,ARTICLE!$B$2:$J$200,5,FALSE)),"") | F18: =IFERROR(IF(ISBLANK(VLOOKUP($B18,ARTICLE!$B$2:$J$200,6,FALSE)),"",VLOOKUP($B18,ARTICLE!$B$2:$J$200,6,FALSE)),"") | G18: =IFERROR(IF(ISBLANK(VLOOKUP($B18,ARTICLE!$B$2:$J$200,7,FALSE)),"",VLOOKUP($B18,ARTICLE!$B$2:$J$200,7,FALSE)),"") | H18: =IFERROR(IF(ISBLANK(VLOOKUP($B18,ARTICLE!$B$2:$J$200,8,FALSE)),"",VLOOKUP($B18,ARTICLE!$B$2:$J$200,8,FALSE)),"")
C19: =IFERROR(IF(ISBLANK(VLOOKUP($B19,ARTICLE!$B$2:$J$200,3,FALSE)),"",VLOOKUP($B19,ARTICLE!$B$2:$J$200,3,FALSE)),"") | D19: =IFERROR(IF(ISBLANK(VLOOKUP($B19,ARTICLE!$B$2:$J$200,4,FALSE)),"",VLOOKUP($B19,ARTICLE!$B$2:$J$200,4,FALSE)),"") | E19: =IFERROR(IF(ISBLANK(VLOOKUP($B19,ARTICLE!$B$2:$J$200,5,FALSE)),"",VLOOKUP($B19,ARTICLE!$B$2:$J$200,5,FALSE)),"") | F19: =IFERROR(IF(ISBLANK(VLOOKUP($B19,ARTICLE!$B$2:$J$200,6,FALSE)),"",VLOOKUP($B19,ARTICLE!$B$2:$J$200,6,FALSE)),"") | G19: =IFERROR(IF(ISBLANK(VLOOKUP($B19,ARTICLE!$B$2:$J$200,7,FALSE)),"",VLOOKUP($B19,ARTICLE!$B$2:$J$200,7,FALSE)),"") | H19: =IFERROR(IF(ISBLANK(VLOOKUP($B19,ARTICLE!$B$2:$J$200,8,FALSE)),"",VLOOKUP($B19,ARTICLE!$B$2:$J$200,8,FALSE)),"")
C20: =IFERROR(IF(ISBLANK(VLOOKUP($B20,ARTICLE!$B$2:$J$200,3,FALSE)),"",VLOOKUP($B20,ARTICLE!$B$2:$J$200,3,FALSE)),"") | D20: =IFERROR(IF(ISBLANK(VLOOKUP($B20,ARTICLE!$B$2:$J$200,4,FALSE)),"",VLOOKUP($B20,ARTICLE!$B$2:$J$200,4,FALSE)),"") | E20: =IFERROR(IF(ISBLANK(VLOOKUP($B20,ARTICLE!$B$2:$J$200,5,FALSE)),"",VLOOKUP($B20,ARTICLE!$B$2:$J$200,5,FALSE)),"") | F20: =IFERROR(IF(ISBLANK(VLOOKUP($B20,ARTICLE!$B$2:$J$200,6,FALSE)),"",VLOOKUP($B20,ARTICLE!$B$2:$J$200,6,FALSE)),"") | G20: =IFERROR(IF(ISBLANK(VLOOKUP($B20,ARTICLE!$B$2:$J$200,7,FALSE)),"",VLOOKUP($B20,ARTICLE!$B$2:$J$200,7,FALSE)),"") | H20: =IFERROR(IF(ISBLANK(VLOOKUP($B20,ARTICLE!$B$2:$J$200,8,FALSE)),"",VLOOKUP($B20,ARTICLE!$B$2:$J$200,8,FALSE)),"")
C21: =IFERROR(IF(ISBLANK(VLOOKUP($B21,ARTICLE!$B$2:$J$200,3,FALSE)),"",VLOOKUP($B21,ARTICLE!$B$2:$J$200,3,FALSE)),"") | D21: =IFERROR(IF(ISBLANK(VLOOKUP($B21,ARTICLE!$B$2:$J$200,4,FALSE)),"",VLOOKUP($B21,ARTICLE!$B$2:$J$200,4,FALSE)),"") | E21: =IFERROR(IF(ISBLANK(VLOOKUP($B21,ARTICLE!$B$2:$J$200,5,FALSE)),"",VLOOKUP($B21,ARTICLE!$B$2:$J$200,5,FALSE)),"") | F21: =IFERROR(IF(ISBLANK(VLOOKUP($B21,ARTICLE!$B$2:$J$200,6,FALSE)),"",VLOOKUP($B21,ARTICLE!$B$2:$J$200,6,FALSE)),"") | G21: =IFERROR(IF(ISBLANK(VLOOKUP($B21,ARTICLE!$B$2:$J$200,7,FALSE)),"",VLOOKUP($B21,ARTICLE!$B$2:$J$200,7,FALSE)),"") | H21: =IFERROR(IF(ISBLANK(VLOOKUP($B21,ARTICLE!$B$2:$J$200,8,FALSE)),"",VLOOKUP($B21,ARTICLE!$B$2:$J$200,8,FALSE)),"")
C22: =IFERROR(IF(ISBLANK(VLOOKUP($B22,ARTICLE!$B$2:$J$200,3,FALSE)),"",VLOOKUP($B22,ARTICLE!$B$2:$J$200,3,FALSE)),"") | D22: =IFERROR(IF(ISBLANK(VLOOKUP($B22,ARTICLE!$B$2:$J$200,4,FALSE)),"",VLOOKUP($B22,ARTICLE!$B$2:$J$200,4,FALSE)),"") | E22: =IFERROR(IF(ISBLANK(VLOOKUP($B22,ARTICLE!$B$2:$J$200,5,FALSE)),"",VLOOKUP($B22,ARTICLE!$B$2:$J$200,5,FALSE)),"") | F22: =IFERROR(IF(ISBLANK(VLOOKUP($B22,ARTICLE!$B$2:$J$200,6,FALSE)),"",VLOOKUP($B22,ARTICLE!$B$2:$J$200,6,FALSE)),"") | G22: =IFERROR(IF(ISBLANK(VLOOKUP($B22,ARTICLE!$B$2:$J$200,7,FALSE)),"",VLOOKUP($B22,ARTICLE!$B$2:$J$200,7,FALSE)),"") | H22: =IFERROR(IF(ISBLANK(VLOOKUP($B22,ARTICLE!$B$2:$J$200,8,FALSE)),"",VLOOKUP($B22,ARTICLE!$B$2:$J$200,8,FALSE)),"")
C23: =IFERROR(IF(ISBLANK(VLOOKUP($B23,ARTICLE!$B$2:$J$200,3,FALSE)),"",VLOOKUP($B23,ARTICLE!$B$2:$J$200,3,FALSE)),"") | D23: =IFERROR(IF(ISBLANK(VLOOKUP($B23,ARTICLE!$B$2:$J$200,4,FALSE)),"",VLOOKUP($B23,ARTICLE!$B$2:$J$200,4,FALSE)),"") | E23: =IFERROR(IF(ISBLANK(VLOOKUP($B23,ARTICLE!$B$2:$J$200,5,FALSE)),"",VLOOKUP($B23,ARTICLE!$B$2:$J$200,5,FALSE)),"") | F23: =IFERROR(IF(ISBLANK(VLOOKUP($B23,ARTICLE!$B$2:$J$200,6,FALSE)),"",VLOOKUP($B23,ARTICLE!$B$2:$J$200,6,FALSE)),"") | G23: =IFERROR(IF(ISBLANK(VLOOKUP($B23,ARTICLE!$B$2:$J$200,7,FALSE)),"",VLOOKUP($B23,ARTICLE!$B$2:$J$200,7,FALSE)),"") | H23: =IFERROR(IF(ISBLANK(VLOOKUP($B23,ARTICLE!$B$2:$J$200,8,FALSE)),"",VLOOKUP($B23,ARTICLE!$B$2:$J$200,8,FALSE)),"")
A24: =B24 -> Structure 100 mm / Bardage horizontal cl4 | B24: =CONCATENATE(B25,IF(B26="",""," / "),B26,IF(B27="",""," / "),B27,IF(B28="",""," / "),B28,IF(B29="",""," / "),B29,IF(B30="",""," / "),B30,IF(B31="",""," / "),B31,B31,IF(B32="",""," / "),B32) -> Structure 100 mm / Bardage horizontal cl4 | C24: =C25 -> m2 | D24: =IF(SUM(E24:H24)=0,0,SUM(E24:H24)) -> 61.764948 | E24: =SUM(E25:E34) -> 36.342271 | F24: =SUM(F25:F34) -> 6.85 | G24: =SUM(G25:G34) -> 12.957681 | H24: =SUM(H25:H34) -> 5.6149952 | I24: PEST-10-BARDAGE | J24: ='MODELE LAROX'!E31 -> 527 | K24: =ROUNDUP(D24,0)*J24 -> 32674 | L24: =ROUNDUP(J24*E24,0) -> 19153 | M24: =L24/K24 -> 0.58618473 | N24: =ROUNDUP(J24*F24,0) -> 3610 | O24: =N24/K24 -> 0.1104854 | P24: =ROUNDUP(J24*G24,0) -> 6829 | Q24: =P24/K24 -> 0.2090041 | R24: =ROUNDUP(J24*H24,0) -> 2960 | S24: =R24/K24 -> 0.090591908
B25: Structure 100 mm | C25: =IFERROR(IF(ISBLANK(VLOOKUP($B25,ARTICLE!$B$2:$J$200,3,FALSE)),"",VLOOKUP($B25,ARTICLE!$B$2:$J$200,3,FALSE)),"") -> m2 | D25: =IFERROR(IF(ISBLANK(VLOOKUP($B25,ARTICLE!$B$2:$J$200,4,FALSE)),"",VLOOKUP($B25,ARTICLE!$B$2:$J$200,4,FALSE)),"") -> 32.392748 | E25: =IFERROR(IF(ISBLANK(VLOOKUP($B25,ARTICLE!$B$2:$J$200,5,FALSE)),"",VLOOKUP($B25,ARTICLE!$B$2:$J$200,5,FALSE)),"") -> 18.822271 | F25: =IFERROR(IF(ISBLANK(VLOOKUP($B25,ARTICLE!$B$2:$J$200,6,FALSE)),"",VLOOKUP($B25,ARTICLE!$B$2:$J$200,6,FALSE)),"") -> 3.83 | G25: =IFERROR(IF(ISBLANK(VLOOKUP($B25,ARTICLE!$B$2:$J$200,7,FALSE)),"",VLOOKUP($B25,ARTICLE!$B$2:$J$200,7,FALSE)),"") -> 6.7956813 | H25: =IFERROR(IF(ISBLANK(VLOOKUP($B25,ARTICLE!$B$2:$J$200,8,FALSE)),"",VLOOKUP($B25,ARTICLE!$B$2:$J$200,8,FALSE)),"") -> 2.9447952
B26: Bardage horizontal cl4 | C26: =IFERROR(IF(ISBLANK(VLOOKUP($B26,ARTICLE!$B$2:$J$200,3,FALSE)),"",VLOOKUP($B26,ARTICLE!$B$2:$J$200,3,FALSE)),"") -> m2 | D26: =IFERROR(IF(ISBLANK(VLOOKUP($B26,ARTICLE!$B$2:$J$200,4,FALSE)),"",VLOOKUP($B26,ARTICLE!$B$2:$J$200,4,FALSE)),"") -> 29.3722 | E26: =IFERROR(IF(ISBLANK(VLOOKUP($B26,ARTICLE!$B$2:$J$200,5,FALSE)),"",VLOOKUP($B26,ARTICLE!$B$2:$J$200,5,FALSE)),"") -> 17.52 | F26: =IFERROR(IF(ISBLANK(VLOOKUP($B26,ARTICLE!$B$2:$J$200,6,FALSE)),"",VLOOKUP($B26,ARTICLE!$B$2:$J$200,6,FALSE)),"") -> 3.02 | G26: =IFERROR(IF(ISBLANK(VLOOKUP($B26,ARTICLE!$B$2:$J$200,7,FALSE)),"",VLOOKUP($B26,ARTICLE!$B$2:$J$200,7,FALSE)),"") -> 6.162 | H26: =IFERROR(IF(ISBLANK(VLOOKUP($B26,ARTICLE!$B$2:$J$200,8,FALSE)),"",VLOOKUP($B26,ARTICLE!$B$2:$J$200,8,FALSE)),"") -> 2.6702
C27: =IFERROR(IF(ISBLANK(VLOOKUP($B27,ARTICLE!$B$2:$J$200,3,FALSE)),"",VLOOKUP($B27,ARTICLE!$B$2:$J$200,3,FALSE)),"") | D27: =IFERROR(IF(ISBLANK(VLOOKUP($B27,ARTICLE!$B$2:$J$200,4,FALSE)),"",VLOOKUP($B27,ARTICLE!$B$2:$J$200,4,FALSE)),"") | E27: =IFERROR(IF(ISBLANK(VLOOKUP($B27,ARTICLE!$B$2:$J$200,5,FALSE)),"",VLOOKUP($B27,ARTICLE!$B$2:$J$200,5,FALSE)),"") | F27: =IFERROR(IF(ISBLANK(VLOOKUP($B27,ARTICLE!$B$2:$J$200,6,FALSE)),"",VLOOKUP($B27,ARTICLE!$B$2:$J$200,6,FALSE)),"") | G27: =IFERROR(IF(ISBLANK(VLOOKUP($B27,ARTICLE!$B$2:$J$200,7,FALSE)),"",VLOOKUP($B27,ARTICLE!$B$2:$J$200,7,FALSE)),"") | H27: =IFERROR(IF(ISBLANK(VLOOKUP($B27,ARTICLE!$B$2:$J$200,8,FALSE)),"",VLOOKUP($B27,ARTICLE!$B$2:$J$200,8,FALSE)),"")
C28: =IFERROR(IF(ISBLANK(VLOOKUP($B28,ARTICLE!$B$2:$J$200,3,FALSE)),"",VLOOKUP($B28,ARTICLE!$B$2:$J$200,3,FALSE)),"") | D28: =IFERROR(IF(ISBLANK(VLOOKUP($B28,ARTICLE!$B$2:$J$200,4,FALSE)),"",VLOOKUP($B28,ARTICLE!$B$2:$J$200,4,FALSE)),"") | E28: =IFERROR(IF(ISBLANK(VLOOKUP($B28,ARTICLE!$B$2:$J$200,5,FALSE)),"",VLOOKUP($B28,ARTICLE!$B$2:$J$200,5,FALSE)),"") | F28: =IFERROR(IF(ISBLANK(VLOOKUP($B28,ARTICLE!$B$2:$J$200,6,FALSE)),"",VLOOKUP($B28,ARTICLE!$B$2:$J$200,6,FALSE)),"") | G28: =IFERROR(IF(ISBLANK(VLOOKUP($B28,ARTICLE!$B$2:$J$200,7,FALSE)),"",VLOOKUP($B28,ARTICLE!$B$2:$J$200,7,FALSE)),"") | H28: =IFERROR(IF(ISBLANK(VLOOKUP($B28,ARTICLE!$B$2:$J$200,8,FALSE)),"",VLOOKUP($B28,ARTICLE!$B$2:$J$200,8,FALSE)),"")
C29: =IFERROR(IF(ISBLANK(VLOOKUP($B29,ARTICLE!$B$2:$J$200,3,FALSE)),"",VLOOKUP($B29,ARTICLE!$B$2:$J$200,3,FALSE)),"") | D29: =IFERROR(IF(ISBLANK(VLOOKUP($B29,ARTICLE!$B$2:$J$200,4,FALSE)),"",VLOOKUP($B29,ARTICLE!$B$2:$J$200,4,FALSE)),"") | E29: =IFERROR(IF(ISBLANK(VLOOKUP($B29,ARTICLE!$B$2:$J$200,5,FALSE)),"",VLOOKUP($B29,ARTICLE!$B$2:$J$200,5,FALSE)),"") | F29: =IFERROR(IF(ISBLANK(VLOOKUP($B29,ARTICLE!$B$2:$J$200,6,FALSE)),"",VLOOKUP($B29,ARTICLE!$B$2:$J$200,6,FALSE)),"") | G29: =IFERROR(IF(ISBLANK(VLOOKUP($B29,ARTICLE!$B$2:$J$200,7,FALSE)),"",VLOOKUP($B29,ARTICLE!$B$2:$J$200,7,FALSE)),"") | H29: =IFERROR(IF(ISBLANK(VLOOKUP($B29,ARTICLE!$B$2:$J$200,8,FALSE)),"",VLOOKUP($B29,ARTICLE!$B$2:$J$200,8,FALSE)),"")
C30: =IFERROR(IF(ISBLANK(VLOOKUP($B30,ARTICLE!$B$2:$J$200,3,FALSE)),"",VLOOKUP($B30,ARTICLE!$B$2:$J$200,3,FALSE)),"") | D30: =IFERROR(IF(ISBLANK(VLOOKUP($B30,ARTICLE!$B$2:$J$200,4,FALSE)),"",VLOOKUP($B30,ARTICLE!$B$2:$J$200,4,FALSE)),"") | E30: =IFERROR(IF(ISBLANK(VLOOKUP($B30,ARTICLE!$B$2:$J$200,5,FALSE)),"",VLOOKUP($B30,ARTICLE!$B$2:$J$200,5,FALSE)),"") | F30: =IFERROR(IF(ISBLANK(VLOOKUP($B30,ARTICLE!$B$2:$J$200,6,FALSE)),"",VLOOKUP($B30,ARTICLE!$B$2:$J$200,6,FALSE)),"") | G30: =IFERROR(IF(ISBLANK(VLOOKUP($B30,ARTICLE!$B$2:$J$200,7,FALSE)),"",VLOOKUP($B30,ARTICLE!$B$2:$J$200,7,FALSE)),"") | H30: =IFERROR(IF(ISBLANK(VLOOKUP($B30,ARTICLE!$B$2:$J$200,8,FALSE)),"",VLOOKUP($B30,ARTICLE!$B$2:$J$200,8,FALSE)),"")
C31: =IFERROR(IF(ISBLANK(VLOOKUP($B31,ARTICLE!$B$2:$J$200,3,FALSE)),"",VLOOKUP($B31,ARTICLE!$B$2:$J$200,3,FALSE)),"") | D31: =IFERROR(IF(ISBLANK(VLOOKUP($B31,ARTICLE!$B$2:$J$200,4,FALSE)),"",VLOOKUP($B31,ARTICLE!$B$2:$J$200,4,FALSE)),"") | E31: =IFERROR(IF(ISBLANK(VLOOKUP($B31,ARTICLE!$B$2:$J$200,5,FALSE)),"",VLOOKUP($B31,ARTICLE!$B$2:$J$200,5,FALSE)),"") | F31: =IFERROR(IF(ISBLANK(VLOOKUP($B31,ARTICLE!$B$2:$J$200,6,FALSE)),"",VLOOKUP($B31,ARTICLE!$B$2:$J$200,6,FALSE)),"") | G31: =IFERROR(IF(ISBLANK(VLOOKUP($B31,ARTICLE!$B$2:$J$200,7,FALSE)),"",VLOOKUP($B31,ARTICLE!$B$2:$J$200,7,FALSE)),"") | H31: =IFERROR(IF(ISBLANK(VLOOKUP($B31,ARTICLE!$B$2:$J$200,8,FALSE)),"",VLOOKUP($B31,ARTICLE!$B$2:$J$200,8,FALSE)),"")
C32: =IFERROR(IF(ISBLANK(VLOOKUP($B32,ARTICLE!$B$2:$J$200,3,FALSE)),"",VLOOKUP($B32,ARTICLE!$B$2:$J$200,3,FALSE)),"") | D32: =IFERROR(IF(ISBLANK(VLOOKUP($B32,ARTICLE!$B$2:$J$200,4,FALSE)),"",VLOOKUP($B32,ARTICLE!$B$2:$J$200,4,FALSE)),"") | E32: =IFERROR(IF(ISBLANK(VLOOKUP($B32,ARTICLE!$B$2:$J$200,5,FALSE)),"",VLOOKUP($B32,ARTICLE!$B$2:$J$200,5,FALSE)),"") | F32: =IFERROR(IF(ISBLANK(VLOOKUP($B32,ARTICLE!$B$2:$J$200,6,FALSE)),"",VLOOKUP($B32,ARTICLE!$B$2:$J$200,6,FALSE)),"") | G32: =IFERROR(IF(ISBLANK(VLOOKUP($B32,ARTICLE!$B$2:$J$200,7,FALSE)),"",VLOOKUP($B32,ARTICLE!$B$2:$J$200,7,FALSE)),"") | H32: =IFERROR(IF(ISBLANK(VLOOKUP($B32,ARTICLE!$B$2:$J$200,8,FALSE)),"",VLOOKUP($B32,ARTICLE!$B$2:$J$200,8,FALSE)),"")
C33: =IFERROR(IF(ISBLANK(VLOOKUP($B33,ARTICLE!$B$2:$J$200,3,FALSE)),"",VLOOKUP($B33,ARTICLE!$B$2:$J$200,3,FALSE)),"") | D33: =IFERROR(IF(ISBLANK(VLOOKUP($B33,ARTICLE!$B$2:$J$200,4,FALSE)),"",VLOOKUP($B33,ARTICLE!$B$2:$J$200,4,FALSE)),"") | E33: =IFERROR(IF(ISBLANK(VLOOKUP($B33,ARTICLE!$B$2:$J$200,5,FALSE)),"",VLOOKUP($B33,ARTICLE!$B$2:$J$200,5,FALSE)),"") | F33: =IFERROR(IF(ISBLANK(VLOOKUP($B33,ARTICLE!$B$2:$J$200,6,FALSE)),"",VLOOKUP($B33,ARTICLE!$B$2:$J$200,6,FALSE)),"") | G33: =IFERROR(IF(ISBLANK(VLOOKUP($B33,ARTICLE!$B$2:$J$200,7,FALSE)),"",VLOOKUP($B33,ARTICLE!$B$2:$J$200,7,FALSE)),"") | H33: =IFERROR(IF(ISBLANK(VLOOKUP($B33,ARTICLE!$B$2:$J$200,8,FALSE)),"",VLOOKUP($B33,ARTICLE!$B$2:$J$200,8,FALSE)),"")
C34: =IFERROR(IF(ISBLANK(VLOOKUP($B34,ARTICLE!$B$2:$J$200,3,FALSE)),"",VLOOKUP($B34,ARTICLE!$B$2:$J$200,3,FALSE)),"") | D34: =IFERROR(IF(ISBLANK(VLOOKUP($B34,ARTICLE!$B$2:$J$200,4,FALSE)),"",VLOOKUP($B34,ARTICLE!$B$2:$J$200,4,FALSE)),"") | E34: =IFERROR(IF(ISBLANK(VLOOKUP($B34,ARTICLE!$B$2:$J$200,5,FALSE)),"",VLOOKUP($B34,ARTICLE!$B$2:$J$200,5,FALSE)),"") | F34: =IFERROR(IF(ISBLANK(VLOOKUP($B34,ARTICLE!$B$2:$J$200,6,FALSE)),"",VLOOKUP($B34,ARTICLE!$B$2:$J$200,6,FALSE)),"") | G34: =IFERROR(IF(ISBLANK(VLOOKUP($B34,ARTICLE!$B$2:$J$200,7,FALSE)),"",VLOOKUP($B34,ARTICLE!$B$2:$J$200,7,FALSE)),"") | H34: =IFERROR(IF(ISBLANK(VLOOKUP($B34,ARTICLE!$B$2:$J$200,8,FALSE)),"",VLOOKUP($B34,ARTICLE!$B$2:$J$200,8,FALSE)),"")
A35: =B35 -> Structure 100 mm / Bardage horizontal cl4 / Pignon | B35: =CONCATENATE(B36,IF(B37="",""," / "),B37,IF(B38="",""," / "),B38,IF(B39="",""," / "),B39,IF(B40="",""," / "),B40,IF(B41="",""," / "),B41,IF(B42="",""," / "),B42,B42,IF(B43="",""," / "),B43) -> Structure 100 mm / Bardage horizontal cl4 / Pignon | C35: =C36 -> m2 | D35: =IF(SUM(E35:H35)=0,0,SUM(E35:H35)) -> 79.468348 | E35: =SUM(E36:E45) -> 36.342271 | F35: =SUM(F36:F45) -> 19.23 | G35: =SUM(G36:G45) -> 16.671681 | H35: =SUM(H36:H45) -> 7.2243952 | I35: PEST-10-BARDAGE PIGNON | J35: ='MODELE LAROX'!E32 -> 100 | K35: =ROUNDUP(D35,0)*J35 -> 8000 | L35: =ROUNDUP(J35*E35,0) -> 3635 | M35: =L35/K35 -> 0.454375 | N35: =ROUNDUP(J35*F35,0) -> 1923 | O35: =N35/K35 -> 0.240375 | P35: =ROUNDUP(J35*G35,0) -> 1668 | Q35: =P35/K35 -> 0.2085 | R35: =ROUNDUP(J35*H35,0) -> 723 | S35: =R35/K35 -> 0.090375
B36: Structure 100 mm | C36: =IFERROR(IF(ISBLANK(VLOOKUP($B36,ARTICLE!$B$2:$J$200,3,FALSE)),"",VLOOKUP($B36,ARTICLE!$B$2:$J$200,3,FALSE)),"") -> m2 | D36: =IFERROR(IF(ISBLANK(VLOOKUP($B36,ARTICLE!$B$2:$J$200,4,FALSE)),"",VLOOKUP($B36,ARTICLE!$B$2:$J$200,4,FALSE)),"") -> 32.392748 | E36: =IFERROR(IF(ISBLANK(VLOOKUP($B36,ARTICLE!$B$2:$J$200,5,FALSE)),"",VLOOKUP($B36,ARTICLE!$B$2:$J$200,5,FALSE)),"") -> 18.822271 | F36: =IFERROR(IF(ISBLANK(VLOOKUP($B36,ARTICLE!$B$2:$J$200,6,FALSE)),"",VLOOKUP($B36,ARTICLE!$B$2:$J$200,6,FALSE)),"") -> 3.83 | G36: =IFERROR(IF(ISBLANK(VLOOKUP($B36,ARTICLE!$B$2:$J$200,7,FALSE)),"",VLOOKUP($B36,ARTICLE!$B$2:$J$200,7,FALSE)),"") -> 6.7956813 | H36: =IFERROR(IF(ISBLANK(VLOOKUP($B36,ARTICLE!$B$2:$J$200,8,FALSE)),"",VLOOKUP($B36,ARTICLE!$B$2:$J$200,8,FALSE)),"") -> 2.9447952
B37: Bardage horizontal cl4 | C37: =IFERROR(IF(ISBLANK(VLOOKUP($B37,ARTICLE!$B$2:$J$200,3,FALSE)),"",VLOOKUP($B37,ARTICLE!$B$2:$J$200,3,FALSE)),"") -> m2 | D37: =IFERROR(IF(ISBLANK(VLOOKUP($B37,ARTICLE!$B$2:$J$200,4,FALSE)),"",VLOOKUP($B37,ARTICLE!$B$2:$J$200,4,FALSE)),"") -> 29.3722 | E37: =IFERROR(IF(ISBLANK(VLOOKUP($B37,ARTICLE!$B$2:$J$200,5,FALSE)),"",VLOOKUP($B37,ARTICLE!$B$2:$J$200,5,FALSE)),"") -> 17.52 | F37: =IFERROR(IF(ISBLANK(VLOOKUP($B37,ARTICLE!$B$2:$J$200,6,FALSE)),"",VLOOKUP($B37,ARTICLE!$B$2:$J$200,6,FALSE)),"") -> 3.02 | G37: =IFERROR(IF(ISBLANK(VLOOKUP($B37,ARTICLE!$B$2:$J$200,7,FALSE)),"",VLOOKUP($B37,ARTICLE!$B$2:$J$200,7,FALSE)),"") -> 6.162 | H37: =IFERROR(IF(ISBLANK(VLOOKUP($B37,ARTICLE!$B$2:$J$200,8,FALSE)),"",VLOOKUP($B37,ARTICLE!$B$2:$J$200,8,FALSE)),"") -> 2.6702
B38: Pignon | C38: =IFERROR(IF(ISBLANK(VLOOKUP($B38,ARTICLE!$B$2:$J$200,3,FALSE)),"",VLOOKUP($B38,ARTICLE!$B$2:$J$200,3,FALSE)),"") -> m2 | D38: =IFERROR(IF(ISBLANK(VLOOKUP($B38,ARTICLE!$B$2:$J$200,4,FALSE)),"",VLOOKUP($B38,ARTICLE!$B$2:$J$200,4,FALSE)),"") -> 17.7034 | E38: =IFERROR(IF(ISBLANK(VLOOKUP($B38,ARTICLE!$B$2:$J$200,5,FALSE)),"",VLOOKUP($B38,ARTICLE!$B$2:$J$200,5,FALSE)),"") -> 0 | F38: =IFERROR(IF(ISBLANK(VLOOKUP($B38,ARTICLE!$B$2:$J$200,6,FALSE)),"",VLOOKUP($B38,ARTICLE!$B$2:$J$200,6,FALSE)),"") -> 12.38 | G38: =IFERROR(IF(ISBLANK(VLOOKUP($B38,ARTICLE!$B$2:$J$200,7,FALSE)),"",VLOOKUP($B38,ARTICLE!$B$2:$J$200,7,FALSE)),"") -> 3.714 | H38: =IFERROR(IF(ISBLANK(VLOOKUP($B38,ARTICLE!$B$2:$J$200,8,FALSE)),"",VLOOKUP($B38,ARTICLE!$B$2:$J$200,8,FALSE)),"") -> 1.6094
C39: =IFERROR(IF(ISBLANK(VLOOKUP($B39,ARTICLE!$B$2:$J$200,3,FALSE)),"",VLOOKUP($B39,ARTICLE!$B$2:$J$200,3,FALSE)),"") | D39: =IFERROR(IF(ISBLANK(VLOOKUP($B39,ARTICLE!$B$2:$J$200,4,FALSE)),"",VLOOKUP($B39,ARTICLE!$B$2:$J$200,4,FALSE)),"") | E39: =IFERROR(IF(ISBLANK(VLOOKUP($B39,ARTICLE!$B$2:$J$200,5,FALSE)),"",VLOOKUP($B39,ARTICLE!$B$2:$J$200,5,FALSE)),"") | F39: =IFERROR(IF(ISBLANK(VLOOKUP($B39,ARTICLE!$B$2:$J$200,6,FALSE)),"",VLOOKUP($B39,ARTICLE!$B$2:$J$200,6,FALSE)),"") | G39: =IFERROR(IF(ISBLANK(VLOOKUP($B39,ARTICLE!$B$2:$J$200,7,FALSE)),"",VLOOKUP($B39,ARTICLE!$B$2:$J$200,7,FALSE)),"") | H39: =IFERROR(IF(ISBLANK(VLOOKUP($B39,ARTICLE!$B$2:$J$200,8,FALSE)),"",VLOOKUP($B39,ARTICLE!$B$2:$J$200,8,FALSE)),"")
C40: =IFERROR(IF(ISBLANK(VLOOKUP($B40,ARTICLE!$B$2:$J$200,3,FALSE)),"",VLOOKUP($B40,ARTICLE!$B$2:$J$200,3,FALSE)),"") | D40: =IFERROR(IF(ISBLANK(VLOOKUP($B40,ARTICLE!$B$2:$J$200,4,FALSE)),"",VLOOKUP($B40,ARTICLE!$B$2:$J$200,4,FALSE)),"") | E40: =IFERROR(IF(ISBLANK(VLOOKUP($B40,ARTICLE!$B$2:$J$200,5,FALSE)),"",VLOOKUP($B40,ARTICLE!$B$2:$J$200,5,FALSE)),"") | F40: =IFERROR(IF(ISBLANK(VLOOKUP($B40,ARTICLE!$B$2:$J$200,6,FALSE)),"",VLOOKUP($B40,ARTICLE!$B$2:$J$200,6,FALSE)),"") | G40: =IFERROR(IF(ISBLANK(VLOOKUP($B40,ARTICLE!$B$2:$J$200,7,FALSE)),"",VLOOKUP($B40,ARTICLE!$B$2:$J$200,7,FALSE)),"") | H40: =IFERROR(IF(ISBLANK(VLOOKUP($B40,ARTICLE!$B$2:$J$200,8,FALSE)),"",VLOOKUP($B40,ARTICLE!$B$2:$J$200,8,FALSE)),"")
...

Sheet Matrice Combo - date
A1: BOTANICAL
A2: OSB 22 RL / Pare-vapeur Sd>28 / Structure PP 260-625 / Laine minérale 150 mm / Laine minérale 100 mm / OSB 8 / Pare-pluie support continu / Lattage 20x45mm | B2: m2 | C2: 118.25836 | D2: 68.138153 | E2: 14.56 | F2: 24.809446 | G2: 10.75076 | H2: PP RDC | I2: 271
A3: OSB 22 RL | B3: m2 | C3: 15.7729 | D3: 9.9 | E3: 1.13 | F3: 3.309 | G3: 1.4339
A4: Pare-vapeur Sd>28 | B4: m2 | C4: 4.719 | D4: 2.75 | E4: 0.55 | F4: 0.99 | G4: 0.429
A5: Structure PP 260-625 | B5: m2 | C5: 44.776729 | D5: 26.722398 | E5: 4.59 | F5: 9.3937194 | G5: 4.0706117
A6: Laine minérale 150 mm | B6: m2 | C6: 18.7902 | D6: 11.84 | E6: 1.3 | F6: 3.942 | G6: 1.7082
A7: Laine minérale 100 mm | B7: m2 | C7: 12.2122 | D7: 7.89 | E7: 0.65 | F7: 2.562 | G7: 1.1102
A8: OSB 8 | B8: m2 | C8: 6.435 | D8: 3.75 | E8: 0.75 | F8: 1.35 | G8: 0.585
A9: Pare-pluie support continu | B9: m2 | C9: 4.8763 | D9: 2.86 | E9: 0.55 | F9: 1.023 | G9: 0.4433
A10: Lattage 20x45mm | B10: m2 | C10: 10.676029 | D10: 2.4257547 | E10: 5.04 | F10: 2.2397264 | G10: 0.97054811
A12: OSB 22 RL / Pare-vapeur Sd>28 / Structure PP 260-625 / Laine minérale 150 mm / Laine minérale 100 mm / OSB 12
A13: OSB 22 RL | B13: m2 | C13: 106.49553 | D13: 65.502398 | E13: 8.97 | F13: 22.341719 | G13: 9.6814117 | H13: PP R+1 | I13: 153
A14: Pare-vapeur Sd>28 | B14: m2 | C14: 15.7729 | D14: 9.9 | E14: 1.13 | F14: 3.309 | G14: 1.4339
A15: Structure PP 260-625 | B15: m2 | C15: 4.719 | D15: 2.75 | E15: 0.55 | F15: 0.99 | G15: 0.429
A16: Laine minérale 150 mm | B16: m2 | C16: 44.776729 | D16: 26.722398 | E16: 4.59 | F16: 9.3937194 | G16: 4.0706117
A17: Laine minérale 100 mm | B17: m2 | C17: 18.7902 | D17: 11.84 | E17: 1.3 | F17: 3.942 | G17: 1.7082
A18: OSB 12 | B18: m2 | C18: 12.2122 | D18: 7.89 | E18: 0.65 | F18: 2.562 | G18: 1.1102
B19: m2 | C19: 10.2245 | D19: 6.4 | E19: 0.75 | F19: 2.145 | G19: 0.9295
A20: OSB 15 / Structure PA 260-625 / Laine minérale 100 mm / Pare-vapeur Sd>28 / OSB 12
A21: OSB 15 | B21: m2 | C21: 86.332529 | D21: 52.082398 | E21: 8.29 | F21: 18.111719 | G21: 7.8484117 | H21: PP ACOPERIS | I21: 211
A22: Structure PA 260-625 | B22: m2 | C22: 12.9701 | D22: 8.32 | E22: 0.75 | F22: 2.721 | G22: 1.1791
A23: Laine minérale 100 mm | B23: m2 | C23: 46.206729 | D23: 26.722398 | E23: 5.59 | F23: 9.6937194 | G23: 4.2006117
A24: Pare-vapeur Sd>28 | B24: m2 | C24: 12.2122 | D24: 7.89 | E24: 0.65 | F24: 2.562 | G24: 1.1102
A25: OSB 12 | B25: m2 | C25: 4.719 | D25: 2.75 | E25: 0.55 | F25: 0.99 | G25: 0.429
A27: OSB 22 / Structure PA 260-416
A28: OSB 22 | B28: m2 | C28: 70.627437 | D28: 41.229816 | E28: 8.16 | F28: 14.816945 | G28: 6.4206761 | H28: PP ACOPERIS VIDERE | I28: 32
A29: Structure PA 260-416 | B29: m2 | C29: 14.1856 | D29: 9.17 | E29: 0.75 | F29: 2.976 | G29: 1.2896
B30: m2 | C30: 56.441837 | D30: 32.059816 | E30: 7.41 | F30: 11.840945 | G30: 5.1310761
A31: ETAULIERS - 23,01,2023
A32: Pare-vapeur SD 90 / Structure 150 mm / Laine minérale 150 mm / OSB 12 / Pare-pluie sur OSB Sd<1,5 m / Lattage 20x45mm | B32: m2 | C32: 89.141901 | D32: 51.096993 | E32: 11.24 | F32: 18.701098 | G32: 8.1038091 | H32: PE-15 | I32: 97
A33: Pare-vapeur SD 90 | B33: m2 | C33: 3.4034 | D33: 1.83 | E33: 0.55 | F33: 0.714 | G33: 0.3094
A34: Structure 150 mm | B34: m2 | C34: 41.171471 | D34: 25.741239 | E34: 3.05 | F34: 8.6373716 | G34: 3.742861
A35: Laine minérale 150 mm | B35: m2 | C35: 18.7902 | D35: 11.84 | E35: 1.3 | F35: 3.942 | G35: 1.7082
A36: OSB 12 | B36: m2 | C36: 10.2245 | D36: 6.4 | E36: 0.75 | F36: 2.145 | G36: 0.9295
A37: Pare-pluie sur OSB Sd<1,5 m | B37: m2 | C37: 4.8763 | D37: 2.86 | E37: 0.55 | F37: 1.023 | G37: 0.4433
A38: Lattage 20x45mm | B38: m2 | C38: 10.676029 | D38: 2.4257547 | E38: 5.04 | F38: 2.2397264 | G38: 0.97054811
A43: Pare-vapeur SD 90 / Structure 150 mm / OSB 12 / Pare-pluie sur OSB Sd<1,5 m / Lattage 20x45mm | B43: m2 | C43: 84.422041 | D43: 39.256993 | E43: 9.94 | F43: 14.759098 | G43: 6.3956091 | H43: PEST-15 | I43: 41
A44: Pare-vapeur SD 90 | B44: m2 | C44: 3.4034 | D44: 1.83 | E44: 0.55 | F44: 0.714 | G44: 0.3094
A45: Structure 150 mm | B45: m2 | C45: 41.171471 | D45: 25.741239 | E45: 3.05 | F45: 8.6373716 | G45: 3.742861
A46: OSB 12 | B46: m2 | C46: 10.2245 | D46: 6.4 | E46: 0.75 | F46: 2.145 | G46: 0.9295
...

Sheet ARTICLE
A1: Liste déroulante | B1: ARTICLES | C1: ID | D1: U | E1: PRIX | F1: MAT | G1: MO | H1: =GESTION!B4 -> 0.3 | I1: =GESTION!B3 -> 0.1
A2: {=_xlfn.UNIQUE(_xlfn._xlws.FILTER('MATRICE ARTICLE'!A2:A1395,NOT(ISBLANK('MATRICE ARTICLE'!A2:A1395))))} -> Structure 50 mm | B2: =IF(A2=0,"",A2) -> Structure 50 mm | D2: =IFERROR(VLOOKUP($B2,'MATRICE ARTICLE'!$A$2:$N$1395,2,FALSE),"") -> m2 | E2: =IF(SUM(F2:I2)=0,"",SUM(F2:I2)) -> 17.228034 | F2: =IFERROR(VLOOKUP($B2,'MATRICE ARTICLE'!$A$2:$N$1395,9,FALSE),"") -> 8.777576 | G2: =IFERROR(VLOOKUP($B2,'MATRICE ARTICLE'!$A$2:$N$1395,14,FALSE),"") -> 3.27 | H2: =IF(SUM(F2:G2)*$H$1=0,"",SUM(F2:G2)*$H$1) -> 3.6142728 | I2: =IF(SUM(F2:H2)*$I$1=0,"",SUM(F2:H2)*$I$1) -> 1.5661849
A3: Structure 100 mm | B3: =IF(A3=0,"",A3) -> Structure 100 mm | D3: =IFERROR(VLOOKUP($B3,'MATRICE ARTICLE'!$A$2:$N$1395,2,FALSE),"") -> m2 | E3: =IF(SUM(F3:I3)=0,"",SUM(F3:I3)) -> 32.392748 | F3: =IFERROR(VLOOKUP($B3,'MATRICE ARTICLE'!$A$2:$N$1395,9,FALSE),"") -> 18.822271 | G3: =IFERROR(VLOOKUP($B3,'MATRICE ARTICLE'!$A$2:$N$1395,14,FALSE),"") -> 3.83 | H3: =IF(SUM(F3:G3)*$H$1=0,"",SUM(F3:G3)*$H$1) -> 6.7956813 | I3: =IF(SUM(F3:H3)*$I$1=0,"",SUM(F3:H3)*$I$1) -> 2.9447952
A4: Structure 145 mm | B4: =IF(A4=0,"",A4) -> Structure 145 mm | D4: =IFERROR(VLOOKUP($B4,'MATRICE ARTICLE'!$A$2:$N$1395,2,FALSE),"") -> m2 | E4: =IF(SUM(F4:I4)=0,"",SUM(F4:I4)) -> 48.442138 | F4: =IFERROR(VLOOKUP($B4,'MATRICE ARTICLE'!$A$2:$N$1395,9,FALSE),"") -> 29.445621 | G4: =IFERROR(VLOOKUP($B4,'MATRICE ARTICLE'!$A$2:$N$1395,14,FALSE),"") -> 4.43 | H4: =IF(SUM(F4:G4)*$H$1=0,"",SUM(F4:G4)*$H$1) -> 10.162686 | I4: =IF(SUM(F4:H4)*$I$1=0,"",SUM(F4:H4)*$I$1) -> 4.4038307
A5: Structure PP 240-250 | B5: =IF(A5=0,"",A5) -> Structure PP 240-250 | D5: =IFERROR(VLOOKUP($B5,'MATRICE ARTICLE'!$A$2:$N$1395,2,FALSE),"") -> m2 | E5: =IF(SUM(F5:I5)=0,"",SUM(F5:I5)) -> 55.89461 | F5: =IFERROR(VLOOKUP($B5,'MATRICE ARTICLE'!$A$2:$N$1395,9,FALSE),"") -> 29.96714 | G5: =IFERROR(VLOOKUP($B5,'MATRICE ARTICLE'!$A$2:$N$1395,14,FALSE),"") -> 9.12 | H5: =IF(SUM(F5:G5)*$H$1=0,"",SUM(F5:G5)*$H$1) -> 11.726142 | I5: =IF(SUM(F5:H5)*$I$1=0,"",SUM(F5:H5)*$I$1) -> 5.0813282
A6: Structure PP 240-313 | B6: =IF(A6=0,"",A6) -> Structure PP 240-313 | D6: =IFERROR(VLOOKUP($B6,'MATRICE ARTICLE'!$A$2:$N$1395,2,FALSE),"") -> m2 | E6: =IF(SUM(F6:I6)=0,"",SUM(F6:I6)) -> 50.799929 | F6: =IFERROR(VLOOKUP($B6,'MATRICE ARTICLE'!$A$2:$N$1395,9,FALSE),"") -> 27.054426 | G6: =IFERROR(VLOOKUP($B6,'MATRICE ARTICLE'!$A$2:$N$1395,14,FALSE),"") -> 8.47 | H6: =IF(SUM(F6:G6)*$H$1=0,"",SUM(F6:G6)*$H$1) -> 10.657328 | I6: =IF(SUM(F6:H6)*$I$1=0,"",SUM(F6:H6)*$I$1) -> 4.6181754
A7: Structure PP 240-416 | B7: =IF(A7=0,"",A7) -> Structure PP 240-416 | D7: =IFERROR(VLOOKUP($B7,'MATRICE ARTICLE'!$A$2:$N$1395,2,FALSE),"") -> m2 | E7: =IF(SUM(F7:I7)=0,"",SUM(F7:I7)) -> 40.867967 | F7: =IFERROR(VLOOKUP($B7,'MATRICE ARTICLE'!$A$2:$N$1395,9,FALSE),"") -> 21.218998 | G7: =IFERROR(VLOOKUP($B7,'MATRICE ARTICLE'!$A$2:$N$1395,14,FALSE),"") -> 7.36 | H7: =IF(SUM(F7:G7)*$H$1=0,"",SUM(F7:G7)*$H$1) -> 8.5736994 | I7: =IF(SUM(F7:H7)*$I$1=0,"",SUM(F7:H7)*$I$1) -> 3.7152697
A8: Structure PP 240-625 | B8: =IF(A8=0,"",A8) -> Structure PP 240-625 | D8: =IFERROR(VLOOKUP($B8,'MATRICE ARTICLE'!$A$2:$N$1395,2,FALSE),"") -> m2 | E8: =IF(SUM(F8:I8)=0,"",SUM(F8:I8)) -> 34.257486 | F8: =IFERROR(VLOOKUP($B8,'MATRICE ARTICLE'!$A$2:$N$1395,9,FALSE),"") -> 18.306284 | G8: =IFERROR(VLOOKUP($B8,'MATRICE ARTICLE'!$A$2:$N$1395,14,FALSE),"") -> 5.65 | H8: =IF(SUM(F8:G8)*$H$1=0,"",SUM(F8:G8)*$H$1) -> 7.1868852 | I8: =IF(SUM(F8:H8)*$I$1=0,"",SUM(F8:H8)*$I$1) -> 3.1143169
A9: Structure PP 260-250 | B9: =IF(A9=0,"",A9) -> Structure PP 260-250 | D9: =IFERROR(VLOOKUP($B9,'MATRICE ARTICLE'!$A$2:$N$1395,2,FALSE),"") -> m2 | E9: =IF(SUM(F9:I9)=0,"",SUM(F9:I9)) -> 59.606311 | F9: =IFERROR(VLOOKUP($B9,'MATRICE ARTICLE'!$A$2:$N$1395,9,FALSE),"") -> 32.392735 | G9: =IFERROR(VLOOKUP($B9,'MATRICE ARTICLE'!$A$2:$N$1395,14,FALSE),"") -> 9.29 | H9: =IF(SUM(F9:G9)*$H$1=0,"",SUM(F9:G9)*$H$1) -> 12.50482 | I9: =IF(SUM(F9:H9)*$I$1=0,"",SUM(F9:H9)*$I$1) -> 5.4187556
A10: Structure PP 260-313 | B10: =IF(A10=0,"",A10) -> Structure PP 260-313 | D10: =IFERROR(VLOOKUP($B10,'MATRICE ARTICLE'!$A$2:$N$1395,2,FALSE),"") -> m2 | E10: =IF(SUM(F10:I10)=0,"",SUM(F10:I10)) -> 66.748237 | F10: =IFERROR(VLOOKUP($B10,'MATRICE ARTICLE'!$A$2:$N$1395,9,FALSE),"") -> 37.467089 | G10: =IFERROR(VLOOKUP($B10,'MATRICE ARTICLE'!$A$2:$N$1395,14,FALSE),"") -> 9.21 | H10: =IF(SUM(F10:G10)*$H$1=0,"",SUM(F10:G10)*$H$1) -> 14.003127 | I10: =IF(SUM(F10:H10)*$I$1=0,"",SUM(F10:H10)*$I$1) -> 6.0680216
A11: Structure PP 260-416 | B11: =IF(A11=0,"",A11) -> Structure PP 260-416 | D11: =IFERROR(VLOOKUP($B11,'MATRICE ARTICLE'!$A$2:$N$1395,2,FALSE),"") -> m2 | E11: =IF(SUM(F11:I11)=0,"",SUM(F11:I11)) -> 57.004437 | F11: =IFERROR(VLOOKUP($B11,'MATRICE ARTICLE'!$A$2:$N$1395,9,FALSE),"") -> 31.753243 | G11: =IFERROR(VLOOKUP($B11,'MATRICE ARTICLE'!$A$2:$N$1395,14,FALSE),"") -> 8.11 | H11: =IF(SUM(F11:G11)*$H$1=0,"",SUM(F11:G11)*$H$1) -> 11.958973 | I11: =IF(SUM(F11:H11)*$I$1=0,"",SUM(F11:H11)*$I$1) -> 5.1822216
A12: Structure PP 260-625 | B12: =IF(A12=0,"",A12) -> Structure PP 260-625 | D12: =IFERROR(VLOOKUP($B12,'MATRICE ARTICLE'!$A$2:$N$1395,2,FALSE),"") -> m2 | E12: =IF(SUM(F12:I12)=0,"",SUM(F12:I12)) -> 47.900423 | F12: =IFERROR(VLOOKUP($B12,'MATRICE ARTICLE'!$A$2:$N$1395,9,FALSE),"") -> 27.216799 | G12: =IFERROR(VLOOKUP($B12,'MATRICE ARTICLE'!$A$2:$N$1395,14,FALSE),"") -> 6.28 | H12: =IF(SUM(F12:G12)*$H$1=0,"",SUM(F12:G12)*$H$1) -> 10.04904 | I12: =IF(SUM(F12:H12)*$I$1=0,"",SUM(F12:H12)*$I$1) -> 4.3545839
A13: Structure PA 240-250 | B13: =IF(A13=0,"",A13) -> Structure PA 240-250 | D13: =IFERROR(VLOOKUP($B13,'MATRICE ARTICLE'!$A$2:$N$1395,2,FALSE),"") -> m2 | E13: =IF(SUM(F13:I13)=0,"",SUM(F13:I13)) -> 58.41141 | F13: =IFERROR(VLOOKUP($B13,'MATRICE ARTICLE'!$A$2:$N$1395,9,FALSE),"") -> 29.96714 | G13: =IFERROR(VLOOKUP($B13,'MATRICE ARTICLE'!$A$2:$N$1395,14,FALSE),"") -> 10.88 | H13: =IF(SUM(F13:G13)*$H$1=0,"",SUM(F13:G13)*$H$1) -> 12.254142 | I13: =IF(SUM(F13:H13)*$I$1=0,"",SUM(F13:H13)*$I$1) -> 5.3101282
A14: Structure PA 240-313 | B14: =IF(A14=0,"",A14) -> Structure PA 240-313 | D14: =IFERROR(VLOOKUP($B14,'MATRICE ARTICLE'!$A$2:$N$1395,2,FALSE),"") -> m2 | E14: =IF(SUM(F14:I14)=0,"",SUM(F14:I14)) -> 53.159429 | F14: =IFERROR(VLOOKUP($B14,'MATRICE ARTICLE'!$A$2:$N$1395,9,FALSE),"") -> 27.054426 | G14: =IFERROR(VLOOKUP($B14,'MATRICE ARTICLE'!$A$2:$N$1395,14,FALSE),"") -> 10.12 | H14: =IF(SUM(F14:G14)*$H$1=0,"",SUM(F14:G14)*$H$1) -> 11.152328 | I14: =IF(SUM(F14:H14)*$I$1=0,"",SUM(F14:H14)*$I$1) -> 4.8326754
... A104: Bardage horizontal cl4 | B104: =IF(A104=0,"",A104) -> Bardage horizontal cl4 | D104: =IFERROR(VLOOKUP($B104,'MATRICE ARTICLE'!$A$2:$N$1395,2,FALSE),"") -> m2 | E104: =IF(SUM(F104:I104)=0,"",SUM(F104:I104)) -> 29.3722 | F104: =IFERROR(VLOOKUP($B104,'MATRICE ARTICLE'!$A$2:$N$1395,9,FALSE),"") -> 17.52 | G104: =IFERROR(VLOOKUP($B104,'MATRICE ARTICLE'!$A$2:$N$1395,14,FALSE),"") -> 3.02 | H104: =IF(SUM(F104:G104)*$H$1=0,"",SUM(F104:G104)*$H$1) -> 6.162 | I104: =IF(SUM(F104:H104)*$I$1=0,"",SUM(F104:H104)*$I$1) -> 2.6702
B105: =IF(A105=0,"",A105) | D105: =IFERROR(VLOOKUP($B105,'MATRICE ARTICLE'!$A$2:$N$1395,2,FALSE),"") | E105: =IF(SUM(F105:I105)=0,"",SUM(F105:I105)) | F105: =IFERROR(VLOOKUP($B105,'MATRICE ARTICLE'!$A$2:$N$1395,9,FALSE),"") | G105: =IFERROR(VLOOKUP($B105,'MATRICE ARTICLE'!$A$2:$N$1395,14,FALSE),"") | H105: =IF(SUM(F105:G105)*$H$1=0,"",SUM(F105:G105)*$H$1) | I105: =IF(SUM(F105:H105)*$I$1=0,"",SUM(F105:H105)*$I$1)
B106: =IF(A106=0,"",A106) | D106: =IFERROR(VLOOKUP($B106,'MATRICE ARTICLE'!$A$2:$N$1395,2,FALSE),"") | E106: =IF(SUM(F106:I106)=0,"",SUM(F106:I106)) | F106: =IFERROR(VLOOKUP($B106,'MATRICE ARTICLE'!$A$2:$N$1395,9,FALSE),"") | G106: =IFERROR(VLOOKUP($B106,'MATRICE ARTICLE'!$A$2:$N$1395,14,FALSE),"") | H106: =IF(SUM(F106:G106)*$H$1=0,"",SUM(F106:G106)*$H$1) | I106: =IF(SUM(F106:H106)*$I$1=0,"",SUM(F106:H106)*$I$1)
B107: =IF(A107=0,"",A107) | D107: =IFERROR(VLOOKUP($B107,'MATRICE ARTICLE'!$A$2:$N$1395,2,FALSE),"") | E107: =IF(SUM(F107:I107)=0,"",SUM(F107:I107)) | F107: =IFERROR(VLOOKUP($B107,'MATRICE ARTICLE'!$A$2:$N$1395,9,FALSE),"") | G107: =IFERROR(VLOOKUP($B107,'MATRICE ARTICLE'!$A$2:$N$1395,14,FALSE),"") | H107: =IF(SUM(F107:G107)*$H$1=0,"",SUM(F107:G107)*$H$1) | I107: =IF(SUM(F107:H107)*$I$1=0,"",SUM(F107:H107)*$I$1)
